Workbook

Sheet Recap Commande Inventaire
B1: Nord mobile 1 | C1: Nord 1 | D1: Nord 2 | E1: Nord mobile 2 | F1: Esplanade | G1: Est mobile 1 | H1: Est 1 | I1: Est mobile 2 | J1: Est mobile 3 | K1: Est 2 | L1: Est mobile 4 | M1: Sud 1 | N1: Sud2 | O1: Principale Modible 1 | P1: Principale 1 | Q1: Principale Modible 2 | R1: Principale Modible 3 | S1: Principale 2 | T1: Principale Modible 4 | U1: Visiteur | V1: Total | W1: Commande
A2: Aligal 2 7kg
A3: Aligal vide
A4: Aligal 2 7kg
A5: Brooklyn EIPA 30lt Fût
A6: Cardinal Blonde 20lt Fût
A7: Servettienne 20lt Fût
A8: Bonde la piece bouteille
A9: Blanche la piece bouteille
A10: IPA la piece bouteille
A11: Grimbergen blanche 20lt Fût
A12: Magners 30lt Fût
A13: Cardinal Blonde Citernes lt
... A231: Consigne Bouteille de gaz de ville

Sheet START

Sheet Inventaire Patinoire & Stade
A1: INVENTAIRE STADE
A4: Catégories | B4: Valeur d'inventaire
A5: Bières | B5: ='Inventaire Generale'!C5 -> 65516.45
A6: Consignes | B6: ='Inventaire Generale'!C6 -> 0
A7: Vins | B7: ='Inventaire Generale'!C7 -> 2310
A8: Boissons avec alcool / Spiritueux | B8: ='Inventaire Generale'!C8 -> 0
A9: Boissons sans alcool | B9: ='Inventaire Generale'!C9 -> 18846.89
A10: Caféterie | B10: ='Inventaire Generale'!C10 -> 0
A11: Negoce | B11: ='Inventaire Generale'!C11 -> 993.12
A12: Boulangerie | B12: ='Inventaire Generale'!C12 -> 0
A13: Sauce & Condiments | B13: ='Inventaire Generale'!C13 -> 1100.91
A14: Surgelés | B14: ='Inventaire Generale'!C14 -> 9168.26
A15: Viandes | B15: ='Inventaire Generale'!C15 -> 0
A16: Graisse & Huile | B16: ='Inventaire Generale'!C16 -> 416
... A19: Divers | B19: ='Inventaire Generale'!C19 -> 0
A20: TOTAL | B20: =B5+B7+B6+B8+B9+B10+B11+B12+B13+B14+B15+B16+B17+B18+B19 -> 103286.08
A22: INVENTAIRE PATINOIRE
A25: Catégories | B25: Valeur d'inventaire
A26: Bières | B26: ='Inventaire General Patinoire'!C5 -> 13977.86
A27: Consignes | B27: ='Inventaire General Patinoire'!C6 -> 200
A28: Vins | B28: ='Inventaire General Patinoire'!C7 -> 2293.475
A29: Boissons avec alcool / Spiritueux | B29: ='Inventaire General Patinoire'!C8 -> 293.15
A30: Boissons sans alcool | B30: ='Inventaire General Patinoire'!C9 -> 6144.54
A31: Caféterie | B31: ='Inventaire General Patinoire'!C10 -> 0
A32: Negoce | B32: ='Inventaire General Patinoire'!C11 -> 1769.72
A33: Boulangerie | B33: ='Inventaire General Patinoire'!C12 -> 0
A34: Sauce & Condiments | B34: ='Inventaire General Patinoire'!C13 -> 951.97
A35: Surgelés | B35: ='Inventaire General Patinoire'!C14 -> 0
A36: Produis Laitiers | B36: ='Inventaire General Patinoire'!C15 -> 0
A37: Graisse & Huile | B37: ='Inventaire General Patinoire'!C16 -> 0
... A40: Divers | B40: ='Inventaire General Patinoire'!C19 -> 270.25
A41: TOTAL | B41: =B26+B27+B28+B29+B30+B31+B32+B33+B34+B35+B36+B37+B38+B39+B40 -> 27425.025
A44: Stade | B44: =B20 -> 103286.08
A45: Patinoire | B45: =B41 -> 27425.025
A46: Total : | B46: =B44+B45 -> 130711.1

Sheet Inventaire Generale
B1: TOTAL PRODUIT CONSOLIDE
B4: Catégories | C4: Valeur d'inventaire
B5: Bières | C5: =J23 -> 65516.45
B6: Consignes | C6: =J4 -> 0
B7: Vins | C7: =J50 -> 2310
B8: Boissons avec alcool / Spiritueux | C8: =J78 -> 0
B9: Boissons sans alcool | C9: =J122 -> 18846.89
B10: Caféterie | C10: =J176 -> 0
B11: Negoce | C11: =J187 -> 993.12
B12: Boulangerie | C12: =J193 -> 0
B13: Sauce & Condiments | C13: =J195 -> 1100.91
B14: Surgelés | C14: =J208 -> 9168.26
B15: Viandes | C15: =J214 -> 0
B16: Graisse & Huile | C16: =J222 -> 416
B17: Mono-usages | C17: =J224 -> 3677.27
B18: Produit de nettoyage | C18: =J245 -> 1257.18
B19: Divers | C19: =J257 -> 0
B20: TOTAL | C20: =C5+C7+C6+C8+C9+C10+C11+C12+C13+C14+C15+C16+C17+C18+C19 -> 103286.08
A21: INVENTAIRES PATINOIRE
B22: Catégorie | C22: Article d'inventaire | D22: MIN. REQUIS | E22: STOCKS | F22: QUANTITE A REMETTRE | G22: MANQUE / RUPTURE | H22: UNITE | I22: PRIX | J22: Valeur d'inventaire
A23: Catégorie :Bières | I23: TOTAL : | J23: =SUM(J24:J40) -> 65516.45
B24: Bières | C24: Aligal 2 7kg | E24: ='Nord 1'!E24+'Nord 2'!E24+'Nord Mobile 1'!E24+'Nord Mobile 2'!E24+Esplanade!E24+'Est mobile 1'!E24+'Est 1'!E24+'Est mobile 2'!E24+'Est Mobile 3'!E24+'Est 2'!E24+'Est mobile 4'!E24+'Réserve Sud'!E24+'Sud 1'!E24+'Sud 2'!E24+Visiteurs!E24+'Principale mobile 1'!E24+'Principale 1 '!E24+'Principale mobile 2'!E24+'Principale mobile 3'!E24+'Principale 2'!E24+'Principale mobile 4'!E24 -> 53 | G24: =SUM('Nord Mobile 1'!G24,'Nord 1'!G24,'Nord 2'!G24,'Nord Mobile 2'!G24,Esplanade!G24,'Est mobile 1'!G24,'Est 1'!G24,'Est mobile 2'!G24,'Est Mobile 3'!G24,'Est 2'!G24,'Est mobile 4'!G24,'Sud 1'!G24,'Sud 2'!G24,Visiteurs!G24,'Principale mobile 1'!G24,'Principale mobile 2'!G24,'Principale mobile 3'!G24,'Principale 2'!G24,'Principale mobile 4'!G24) -> 8 | H24: EA | I24: 55.95 | J24: =E24*I24 -> 2965.35
B25: Bières | C25: Brooklyn EIPA 30lt Fût | E25: ='Nord 1'!E25+'Nord 2'!E25+'Nord Mobile 1'!E25+'Nord Mobile 2'!E25+Esplanade!E25+'Est mobile 1'!E25+'Est 1'!E25+'Est mobile 2'!E25+'Est Mobile 3'!E25+'Est 2'!E25+'Est mobile 4'!E25+'Réserve Sud'!E25+'Sud 1'!E25+'Sud 2'!E25+Visiteurs!E25+'Principale mobile 1'!E25+'Principale 1 '!E25+'Principale mobile 2'!E25+'Principale mobile 3'!E25+'Principale 2'!E25+'Principale mobile 4'!E25 -> 0 | G25: =SUM('Nord Mobile 1'!G25,'Nord 1'!G25,'Nord 2'!G25,'Nord Mobile 2'!G25,Esplanade!G25,'Est mobile 1'!G25,'Est 1'!G25,'Est mobile 2'!G25,'Est Mobile 3'!G25,'Est 2'!G25,'Est mobile 4'!G25,'Sud 1'!G25,'Sud 2'!G25,Visiteurs!G25,'Principale mobile 1'!G25,'Principale mobile 2'!G25,'Principale mobile 3'!G25,'Principale 2'!G25,'Principale mobile 4'!G25) -> 0 | H25: EA | I25: 173.1 | J25: =E25*I25 -> 0
B26: Bières | C26: Cardinal Blonde 20lt Fût | E26: ='Nord 1'!E26+'Nord 2'!E26+'Nord Mobile 1'!E26+'Nord Mobile 2'!E26+Esplanade!E26+'Est mobile 1'!E26+'Est 1'!E26+'Est mobile 2'!E26+'Est Mobile 3'!E26+'Est 2'!E26+'Est mobile 4'!E26+'Réserve Sud'!E26+'Sud 1'!E26+'Sud 2'!E26+Visiteurs!E26+'Principale mobile 1'!E26+'Principale 1 '!E26+'Principale mobile 2'!E26+'Principale mobile 3'!E26+'Principale 2'!E26+'Principale mobile 4'!E26 -> 527 | G26: =SUM('Nord Mobile 1'!G26,'Nord 1'!G26,'Nord 2'!G26,'Nord Mobile 2'!G26,Esplanade!G26,'Est mobile 1'!G26,'Est 1'!G26,'Est mobile 2'!G26,'Est Mobile 3'!G26,'Est 2'!G26,'Est mobile 4'!G26,'Sud 1'!G26,'Sud 2'!G26,Visiteurs!G26,'Principale mobile 1'!G26,'Principale mobile 2'!G26,'Principale mobile 3'!G26,'Principale 2'!G26,'Principale mobile 4'!G26) -> 45 | H26: EA | I26: 75.4 | J26: =E26*I26 -> 39735.8
B27: Bières | C27: Servettienne 20lt Fût | E27: ='Nord 1'!E27+'Nord 2'!E27+'Nord Mobile 1'!E27+'Nord Mobile 2'!E27+Esplanade!E27+'Est mobile 1'!E27+'Est 1'!E27+'Est mobile 2'!E27+'Est Mobile 3'!E27+'Est 2'!E27+'Est mobile 4'!E27+'Réserve Sud'!E27+'Sud 1'!E27+'Sud 2'!E27+Visiteurs!E27+'Principale mobile 1'!E27+'Principale 1 '!E27+'Principale mobile 2'!E27+'Principale mobile 3'!E27+'Principale 2'!E27+'Principale mobile 4'!E27 -> 215 | G27: =SUM('Nord Mobile 1'!G27,'Nord 1'!G27,'Nord 2'!G27,'Nord Mobile 2'!G27,Esplanade!G27,'Est mobile 1'!G27,'Est 1'!G27,'Est mobile 2'!G27,'Est Mobile 3'!G27,'Est 2'!G27,'Est mobile 4'!G27,'Sud 1'!G27,'Sud 2'!G27,Visiteurs!G27,'Principale mobile 1'!G27,'Principale mobile 2'!G27,'Principale mobile 3'!G27,'Principale 2'!G27,'Principale mobile 4'!G27) -> 28 | H27: EA | I27: 84.9 | J27: =E27*I27 -> 18253.5
B28: Bières | C28: Bonde la piece bouteille | E28: ='Nord 1'!E28+'Nord 2'!E28+'Nord Mobile 1'!E28+'Nord Mobile 2'!E28+Esplanade!E28+'Est mobile 1'!E28+'Est 1'!E28+'Est mobile 2'!E28+'Est Mobile 3'!E28+'Est 2'!E28+'Est mobile 4'!E28+'Réserve Sud'!E28+'Sud 1'!E28+'Sud 2'!E28+Visiteurs!E28+'Principale mobile 1'!E28+'Principale 1 '!E28+'Principale mobile 2'!E28+'Principale mobile 3'!E28+'Principale 2'!E28+'Principale mobile 4'!E28 -> 0 | G28: =SUM('Nord Mobile 1'!G28,'Nord 1'!G28,'Nord 2'!G28,'Nord Mobile 2'!G28,Esplanade!G28,'Est mobile 1'!G28,'Est 1'!G28,'Est mobile 2'!G28,'Est Mobile 3'!G28,'Est 2'!G28,'Est mobile 4'!G28,'Sud 1'!G28,'Sud 2'!G28,Visiteurs!G28,'Principale mobile 1'!G28,'Principale mobile 2'!G28,'Principale mobile 3'!G28,'Principale 2'!G28,'Principale mobile 4'!G28) -> 0 | H28: EA | I28: 2.96 | J28: =E28*I28 -> 0
B29: Bières | C29: Blanche la piece bouteille | E29: ='Nord 1'!E29+'Nord 2'!E29+'Nord Mobile 1'!E29+'Nord Mobile 2'!E29+Esplanade!E29+'Est mobile 1'!E29+'Est 1'!E29+'Est mobile 2'!E29+'Est Mobile 3'!E29+'Est 2'!E29+'Est mobile 4'!E29+'Réserve Sud'!E29+'Sud 1'!E29+'Sud 2'!E29+Visiteurs!E29+'Principale mobile 1'!E29+'Principale 1 '!E29+'Principale mobile 2'!E29+'Principale mobile 3'!E29+'Principale 2'!E29+'Principale mobile 4'!E29 -> 0 | G29: =SUM('Nord Mobile 1'!G29,'Nord 1'!G29,'Nord 2'!G29,'Nord Mobile 2'!G29,Esplanade!G29,'Est mobile 1'!G29,'Est 1'!G29,'Est mobile 2'!G29,'Est Mobile 3'!G29,'Est 2'!G29,'Est mobile 4'!G29,'Sud 1'!G29,'Sud 2'!G29,Visiteurs!G29,'Principale mobile 1'!G29,'Principale mobile 2'!G29,'Principale mobile 3'!G29,'Principale 2'!G29,'Principale mobile 4'!G29) -> 0 | H29: EA | I29: 2.96 | J29: =E29*I29 -> 0
B30: Bières | C30: IPA la piece bouteille | E30: ='Nord 1'!E30+'Nord 2'!E30+'Nord Mobile 1'!E30+'Nord Mobile 2'!E30+Esplanade!E30+'Est mobile 1'!E30+'Est 1'!E30+'Est mobile 2'!E30+'Est Mobile 3'!E30+'Est 2'!E30+'Est mobile 4'!E30+'Réserve Sud'!E30+'Sud 1'!E30+'Sud 2'!E30+Visiteurs!E30+'Principale mobile 1'!E30+'Principale 1 '!E30+'Principale mobile 2'!E30+'Principale mobile 3'!E30+'Principale 2'!E30+'Principale mobile 4'!E30 -> 0 | G30: =SUM('Nord Mobile 1'!G30,'Nord 1'!G30,'Nord 2'!G30,'Nord Mobile 2'!G30,Esplanade!G30,'Est mobile 1'!G30,'Est 1'!G30,'Est mobile 2'!G30,'Est Mobile 3'!G30,'Est 2'!G30,'Est mobile 4'!G30,'Sud 1'!G30,'Sud 2'!G30,Visiteurs!G30,'Principale mobile 1'!G30,'Principale mobile 2'!G30,'Principale mobile 3'!G30,'Principale 2'!G30,'Principale mobile 4'!G30) -> 0 | H30: EA | I30: 2.96 | J30: =E30*I30 -> 0
B31: Bières | C31: Grimbergen blanche 20lt Fût | E31: ='Nord 1'!E31+'Nord 2'!E31+'Nord Mobile 1'!E31+'Nord Mobile 2'!E31+Esplanade!E31+'Est mobile 1'!E31+'Est 1'!E31+'Est mobile 2'!E31+'Est Mobile 3'!E31+'Est 2'!E31+'Est mobile 4'!E31+'Réserve Sud'!E31+'Sud 1'!E31+'Sud 2'!E31+Visiteurs!E31+'Principale mobile 1'!E31+'Principale 1 '!E31+'Principale mobile 2'!E31+'Principale mobile 3'!E31+'Principale 2'!E31+'Principale mobile 4'!E31 -> 33 | G31: =SUM('Nord Mobile 1'!G31,'Nord 1'!G31,'Nord 2'!G31,'Nord Mobile 2'!G31,Esplanade!G31,'Est mobile 1'!G31,'Est 1'!G31,'Est mobile 2'!G31,'Est Mobile 3'!G31,'Est 2'!G31,'Est mobile 4'!G31,'Sud 1'!G31,'Sud 2'!G31,Visiteurs!G31,'Principale mobile 1'!G31,'Principale mobile 2'!G31,'Principale mobile 3'!G31,'Principale 2'!G31,'Principale mobile 4'!G31) -> 0 | H31: EA | I31: 107.2 | J31: =E31*I31 -> 3537.6
B32: Bières | C32: Magners 30lt Fût | E32: ='Nord 1'!E32+'Nord 2'!E32+'Nord Mobile 1'!E32+'Nord Mobile 2'!E32+Esplanade!E32+'Est mobile 1'!E32+'Est 1'!E32+'Est mobile 2'!E32+'Est Mobile 3'!E32+'Est 2'!E32+'Est mobile 4'!E32+'Réserve Sud'!E32+'Sud 1'!E32+'Sud 2'!E32+Visiteurs!E32+'Principale mobile 1'!E32+'Principale 1 '!E32+'Principale mobile 2'!E32+'Principale mobile 3'!E32+'Principale 2'!E32+'Principale mobile 4'!E32 -> 6 | G32: =SUM('Nord Mobile 1'!G32,'Nord 1'!G32,'Nord 2'!G32,'Nord Mobile 2'!G32,Esplanade!G32,'Est mobile 1'!G32,'Est 1'!G32,'Est mobile 2'!G32,'Est Mobile 3'!G32,'Est 2'!G32,'Est mobile 4'!G32,'Sud 1'!G32,'Sud 2'!G32,Visiteurs!G32,'Principale mobile 1'!G32,'Principale mobile 2'!G32,'Principale mobile 3'!G32,'Principale 2'!G32,'Principale mobile 4'!G32) -> 0 | H32: EA | I32: 170.7 | J32: =E32*I32 -> 1024.2
B33: Bières | C33: Cardinal Blonde Citernes lt | E33: ='Nord 1'!E33+'Nord 2'!E33+'Nord Mobile 1'!E33+'Nord Mobile 2'!E33+Esplanade!E33+'Est mobile 1'!E33+'Est 1'!E33+'Est mobile 2'!E33+'Est Mobile 3'!E33+'Est 2'!E33+'Est mobile 4'!E33+'Réserve Sud'!E33+'Sud 1'!E33+'Sud 2'!E33+Visiteurs!E33+'Principale mobile 1'!E33+'Principale 1 '!E33+'Principale mobile 2'!E33+'Principale mobile 3'!E33+'Principale 2'!E33+'Principale mobile 4'!E33 -> 0 | G33: =SUM('Nord Mobile 1'!G33,'Nord 1'!G33,'Nord 2'!G33,'Nord Mobile 2'!G33,Esplanade!G33,'Est mobile 1'!G33,'Est 1'!G33,'Est mobile 2'!G33,'Est Mobile 3'!G33,'Est 2'!G33,'Est mobile 4'!G33,'Sud 1'!G33,'Sud 2'!G33,Visiteurs!G33,'Principale mobile 1'!G33,'Principale mobile 2'!G33,'Principale mobile 3'!G33,'Principale 2'!G33,'Principale mobile 4'!G33) -> 0 | H33: lt | I33: 3.77 | J33: =E33*I33 -> 0
B34: Bières | C34: Valaisanne Bière de Cave - Bière bouteille | E34: ='Nord 1'!E34+'Nord 2'!E34+'Nord Mobile 1'!E34+'Nord Mobile 2'!E34+Esplanade!E34+'Est mobile 1'!E34+'Est 1'!E34+'Est mobile 2'!E34+'Est Mobile 3'!E34+'Est 2'!E34+'Est mobile 4'!E34+'Réserve Sud'!E34+'Sud 1'!E34+'Sud 2'!E34+Visiteurs!E34+'Principale mobile 1'!E34+'Principale 1 '!E34+'Principale mobile 2'!E34+'Principale mobile 3'!E34+'Principale 2'!E34+'Principale mobile 4'!E34 -> 0 | G34: =SUM('Nord Mobile 1'!G34,'Nord 1'!G34,'Nord 2'!G34,'Nord Mobile 2'!G34,Esplanade!G34,'Est mobile 1'!G34,'Est 1'!G34,'Est mobile 2'!G34,'Est Mobile 3'!G34,'Est 2'!G34,'Est mobile 4'!G34,'Sud 1'!G34,'Sud 2'!G34,Visiteurs!G34,'Principale mobile 1'!G34,'Principale mobile 2'!G34,'Principale mobile 3'!G34,'Principale 2'!G34,'Principale mobile 4'!G34) -> 0 | H34: EA | I34: 2.56 | J34: =E34*I34 -> 0
B35: Bières | C35: Valaisanne IPA - Bière bouteille | E35: ='Nord 1'!E35+'Nord 2'!E35+'Nord Mobile 1'!E35+'Nord Mobile 2'!E35+Esplanade!E35+'Est mobile 1'!E35+'Est 1'!E35+'Est mobile 2'!E35+'Est Mobile 3'!E35+'Est 2'!E35+'Est mobile 4'!E35+'Réserve Sud'!E35+'Sud 1'!E35+'Sud 2'!E35+Visiteurs!E35+'Principale mobile 1'!E35+'Principale 1 '!E35+'Principale mobile 2'!E35+'Principale mobile 3'!E35+'Principale 2'!E35+'Principale mobile 4'!E35 -> 0 | G35: =SUM('Nord Mobile 1'!G35,'Nord 1'!G35,'Nord 2'!G35,'Nord Mobile 2'!G35,Esplanade!G35,'Est mobile 1'!G35,'Est 1'!G35,'Est mobile 2'!G35,'Est Mobile 3'!G35,'Est 2'!G35,'Est mobile 4'!G35,'Sud 1'!G35,'Sud 2'!G35,Visiteurs!G35,'Principale mobile 1'!G35,'Principale mobile 2'!G35,'Principale mobile 3'!G35,'Principale 2'!G35,'Principale mobile 4'!G35) -> 0 | H35: EA | I35: 3.08 | J35: =E35*I35 -> 0
... B40: Bières | C40: Cidre 33cl "La Genevoise du Terroir" | E40: ='Nord 1'!E40+'Nord 2'!E40+'Nord Mobile 1'!E40+'Nord Mobile 2'!E40+Esplanade!E40+'Est mobile 1'!E40+'Est 1'!E40+'Est mobile 2'!E40+'Est Mobile 3'!E40+'Est 2'!E40+'Est mobile 4'!E40+'Réserve Sud'!E40+'Sud 1'!E40+'Sud 2'!E40+Visiteurs!E40+'Principale mobile 1'!E40+'Principale 1 '!E40+'Principale mobile 2'!E40+'Principale mobile 3'!E40+'Principale 2'!E40+'Principale mobile 4'!E40 -> 0 | G40: =SUM('Nord Mobile 1'!G40,'Nord 1'!G40,'Nord 2'!G40,'Nord Mobile 2'!G40,Esplanade!G40,'Est mobile 1'!G40,'Est 1'!G40,'Est mobile 2'!G40,'Est Mobile 3'!G40,'Est 2'!G40,'Est mobile 4'!G40,'Sud 1'!G40,'Sud 2'!G40,Visiteurs!G40,'Principale mobile 1'!G40,'Principale mobile 2'!G40,'Principale mobile 3'!G40,'Principale 2'!G40,'Principale mobile 4'!G40) -> 0 | H40: EA | I40: 3.45 | J40: =E40*I40 -> 0
A41: Catégorie : Consignes | E41: ='Nord 1'!E41+'Nord 2'!E41+'Nord Mobile 1'!E41+'Nord Mobile 2'!E41+Esplanade!E41+'Est mobile 1'!E41+'Est 1'!E41+'Est mobile 2'!E41+'Est Mobile 3'!E41+'Est 2'!E41+'Est mobile 4'!E41+'Réserve Sud'!E41+'Sud 1'!E41+'Sud 2'!E41+Visiteurs!E41+'Principale mobile 1'!E41+'Principale 1 '!E41+'Principale mobile 2'!E41+'Principale mobile 3'!E41+'Principale 2'!E41+'Principale mobile 4'!E41 -> 0 | G41: =SUM('Nord Mobile 1'!G41,'Nord 1'!G41,'Nord 2'!G41,'Nord Mobile 2'!G41,Esplanade!G41,'Est mobile 1'!G41,'Est 1'!G41,'Est mobile 2'!G41,'Est Mobile 3'!G41,'Est 2'!G41,'Est mobile 4'!G41,'Sud 1'!G41,'Sud 2'!G41,Visiteurs!G41,'Principale mobile 1'!G41,'Principale mobile 2'!G41,'Principale mobile 3'!G41,'Principale 2'!G41,'Principale mobile 4'!G41) -> 0 | I41: TOTAL : | J41: =SUM(J42:J49) -> 41515
B42: Consignes | C42: Bouteille / Aligal consignée | E42: ='Nord 1'!E42+'Nord 2'!E42+'Nord Mobile 1'!E42+'Nord Mobile 2'!E42+Esplanade!E42+'Est mobile 1'!E42+'Est 1'!E42+'Est mobile 2'!E42+'Est Mobile 3'!E42+'Est 2'!E42+'Est mobile 4'!E42+'Réserve Sud'!E42+'Sud 1'!E42+'Sud 2'!E42+Visiteurs!E42+'Principale mobile 1'!E42+'Principale 1 '!E42+'Principale mobile 2'!E42+'Principale mobile 3'!E42+'Principale 2'!E42+'Principale mobile 4'!E42 -> 46 | G42: =SUM('Nord Mobile 1'!G42,'Nord 1'!G42,'Nord 2'!G42,'Nord Mobile 2'!G42,Esplanade!G42,'Est mobile 1'!G42,'Est 1'!G42,'Est mobile 2'!G42,'Est Mobile 3'!G42,'Est 2'!G42,'Est mobile 4'!G42,'Sud 1'!G42,'Sud 2'!G42,Visiteurs!G42,'Principale mobile 1'!G42,'Principale mobile 2'!G42,'Principale mobile 3'!G42,'Principale 2'!G42,'Principale mobile 4'!G42) -> 0 | H42: EA | I42: 100 | J42: =E42*I42 -> 4600
B43: Consignes | C43: Caisse 24bt vides consignées (Sodas) | E43: ='Nord 1'!E43+'Nord 2'!E43+'Nord Mobile 1'!E43+'Nord Mobile 2'!E43+Esplanade!E43+'Est mobile 1'!E43+'Est 1'!E43+'Est mobile 2'!E43+'Est Mobile 3'!E43+'Est 2'!E43+'Est mobile 4'!E43+'Réserve Sud'!E43+'Sud 1'!E43+'Sud 2'!E43+Visiteurs!E43+'Principale mobile 1'!E43+'Principale 1 '!E43+'Principale mobile 2'!E43+'Principale mobile 3'!E43+'Principale 2'!E43+'Principale mobile 4'!E43 -> 0 | G43: =SUM('Nord Mobile 1'!G43,'Nord 1'!G43,'Nord 2'!G43,'Nord Mobile 2'!G43,Esplanade!G43,'Est mobile 1'!G43,'Est 1'!G43,'Est mobile 2'!G43,'Est Mobile 3'!G43,'Est 2'!G43,'Est mobile 4'!G43,'Sud 1'!G43,'Sud 2'!G43,Visiteurs!G43,'Principale mobile 1'!G43,'Principale mobile 2'!G43,'Principale mobile 3'!G43,'Principale 2'!G43,'Principale mobile 4'!G43) -> 0 | H43: EA | I43: 12.2 | J43: =E43*I43 -> 0
B44: Consignes | C44: Caisse 20bt vides consignées (Valser) | E44: ='Nord 1'!E44+'Nord 2'!E44+'Nord Mobile 1'!E44+'Nord Mobile 2'!E44+Esplanade!E44+'Est mobile 1'!E44+'Est 1'!E44+'Est mobile 2'!E44+'Est Mobile 3'!E44+'Est 2'!E44+'Est mobile 4'!E44+'Réserve Sud'!E44+'Sud 1'!E44+'Sud 2'!E44+Visiteurs!E44+'Principale mobile 1'!E44+'Principale 1 '!E44+'Principale mobile 2'!E44+'Principale mobile 3'!E44+'Principale 2'!E44+'Principale mobile 4'!E44 -> 0 | G44: =SUM('Nord Mobile 1'!G44,'Nord 1'!G44,'Nord 2'!G44,'Nord Mobile 2'!G44,Esplanade!G44,'Est mobile 1'!G44,'Est 1'!G44,'Est mobile 2'!G44,'Est Mobile 3'!G44,'Est 2'!G44,'Est mobile 4'!G44,'Sud 1'!G44,'Sud 2'!G44,Visiteurs!G44,'Principale mobile 1'!G44,'Principale mobile 2'!G44,'Principale mobile 3'!G44,'Principale 2'!G44,'Principale mobile 4'!G44) -> 0 | H44: EA | I44: 11 | J44: =E44*I44 -> 0
B45: Consignes | C45: Caisse verres consignés (Bières) | E45: ='Nord 1'!E45+'Nord 2'!E45+'Nord Mobile 1'!E45+'Nord Mobile 2'!E45+Esplanade!E45+'Est mobile 1'!E45+'Est 1'!E45+'Est mobile 2'!E45+'Est Mobile 3'!E45+'Est 2'!E45+'Est mobile 4'!E45+'Réserve Sud'!E45+'Sud 1'!E45+'Sud 2'!E45+Visiteurs!E45+'Principale mobile 1'!E45+'Principale 1 '!E45+'Principale mobile 2'!E45+'Principale mobile 3'!E45+'Principale 2'!E45+'Principale mobile 4'!E45 -> 0 | G45: =SUM('Nord Mobile 1'!G45,'Nord 1'!G45,'Nord 2'!G45,'Nord Mobile 2'!G45,Esplanade!G45,'Est mobile 1'!G45,'Est 1'!G45,'Est mobile 2'!G45,'Est Mobile 3'!G45,'Est 2'!G45,'Est mobile 4'!G45,'Sud 1'!G45,'Sud 2'!G45,Visiteurs!G45,'Principale mobile 1'!G45,'Principale mobile 2'!G45,'Principale mobile 3'!G45,'Principale 2'!G45,'Principale mobile 4'!G45) -> 0 | H45: EA | I45: 5 | J45: =E45*I45 -> 0
B46: Consignes | C46: Caisse BT 1,5L PET consignée | E46: ='Nord 1'!E46+'Nord 2'!E46+'Nord Mobile 1'!E46+'Nord Mobile 2'!E46+Esplanade!E46+'Est mobile 1'!E46+'Est 1'!E46+'Est mobile 2'!E46+'Est Mobile 3'!E46+'Est 2'!E46+'Est mobile 4'!E46+'Réserve Sud'!E46+'Sud 1'!E46+'Sud 2'!E46+Visiteurs!E46+'Principale mobile 1'!E46+'Principale 1 '!E46+'Principale mobile 2'!E46+'Principale mobile 3'!E46+'Principale 2'!E46+'Principale mobile 4'!E46 -> 163 | G46: =SUM('Nord Mobile 1'!G46,'Nord 1'!G46,'Nord 2'!G46,'Nord Mobile 2'!G46,Esplanade!G46,'Est mobile 1'!G46,'Est 1'!G46,'Est mobile 2'!G46,'Est Mobile 3'!G46,'Est 2'!G46,'Est mobile 4'!G46,'Sud 1'!G46,'Sud 2'!G46,Visiteurs!G46,'Principale mobile 1'!G46,'Principale mobile 2'!G46,'Principale mobile 3'!G46,'Principale 2'!G46,'Principale mobile 4'!G46) -> 0 | H46: EA | I46: 5 | J46: =E46*I46 -> 815
...

Sheet Réserve Nord
B1: TOTAL PRODUIT CONSOLIDE
B4: Catégories | C4: Valeur d'inventaire
B5: Bières | C5: =J23 -> 0
B6: Consignes | C6: =J4 -> 0
B7: Vins | C7: =J50 -> 0
B8: Boissons avec alcool / Spiritueux | C8: =J78 -> 0
B9: Boissons sans alcool | C9: =J122 -> 0
B10: Caféterie | C10: =J176 -> 0
B11: Negoce | C11: =J187 -> 0
B12: Boulangerie | C12: =J193 -> 0
B13: Sauce & Condiments | C13: =J195 -> 0
B14: Surgelés | C14: =J208 -> 0
B15: Viandes | C15: =J214 -> 0
B16: Graisse & Huile | C16: =J222 -> 0
B17: Mono-usages | C17: =J224 -> 0
B18: Produit de nettoyage | C18: =J245 -> 0
B19: Divers | C19: =J257 -> 0
B20: TOTAL | C20: =C5+C6+C7+C8+C9+C10+C11+C12+C13+C14+C15+C16+C17+C18+C19 -> 0
A21: INVENTAIRES STADE
B22: Catégorie | C22: Article d'inventaire | E22: STOCKS | F22: QUANTITE A REMETTRE | G22: MANQUE / RUPTURE | H22: UNITE | I22: PRIX | J22: VALEUR
A23: Catégorie :Bières | I23: TOTAL : | J23: =SUM(J24:J40) -> 0
B24: Bières | C24: Aligal 2 7kg | G24: =IF(D24-E24>0,D24-E24,"") | H24: EA | I24: 55.95 | J24: =E24*I24 -> 0
B25: Bières | C25: Brooklyn EIPA 30lt Fût | G25: =IF(D25-E25>0,D25-E25,"") | H25: EA | I25: 173.1 | J25: =E25*I25 -> 0
B26: Bières | C26: Cardinal Blonde 20lt Fût | G26: =IF(D26-E26>0,D26-E26,"") | H26: EA | I26: 75.4 | J26: =E26*I26 -> 0
B27: Bières | C27: Servettienne 20lt Fût | G27: =IF(D27-E27>0,D27-E27,"") | H27: EA | I27: 84.9 | J27: =E27*I27 -> 0
B28: Bières | C28: Bonde la piece bouteille | G28: =IF(D28-E28>0,D28-E28,"") | H28: EA | I28: 2.96 | J28: =E28*I28 -> 0
B29: Bières | C29: Blanche la piece bouteille | G29: =IF(D29-E29>0,D29-E29,"") | H29: EA | I29: 2.96 | J29: =E29*I29 -> 0
B30: Bières | C30: IPA la piece bouteille | G30: =IF(D30-E30>0,D30-E30,"") | H30: EA | I30: 2.96 | J30: =E30*I30 -> 0
B31: Bières | C31: Grimbergen blanche 20lt Fût | G31: =IF(D31-E31>0,D31-E31,"") | H31: EA | I31: 107.2 | J31: =E31*I31 -> 0
B32: Bières | C32: Magners 30lt Fût | G32: =IF(D32-E32>0,D32-E32,"") | H32: EA | I32: 170.7 | J32: =E32*I32 -> 0
B33: Bières | C33: Cardinal Blonde Citernes lt | G33: =IF(D33-E33>0,D33-E33,"") | H33: lt | I33: 3.77 | J33: =E33*I33 -> 0
B34: Bières | C34: Valaisanne Bière de Cave - Bière bouteille | G34: =IF(D34-E34>0,D34-E34,"") | H34: EA | I34: 2.56 | J34: =E34*I34 -> 0
B35: Bières | C35: Valaisanne IPA - Bière bouteille | G35: =IF(D35-E35>0,D35-E35,"") | H35: EA | I35: 3.08 | J35: =E35*I35 -> 0
... B40: Bières | C40: Cidre 33cl "La Genevoise du Terroir" | G40: =IF(D40-E40>0,D40-E40,"") | H40: EA | I40: 3.45 | J40: =E40*I40 -> 0
A41: Catégorie : Consignes | G41: =IF(D41-E41>0,D41-E41,"") | I41: TOTAL : | J41: =SUM(J42:J49) -> 0
B42: Consignes | C42: Bouteille / Aligal consignée | G42: =IF(D42-E42>0,D42-E42,"") | H42: EA | I42: 100 | J42: =E42*I42 -> 0
B43: Consignes | C43: Caisse 24bt vides consignées (Sodas) | G43: =IF(D43-E43>0,D43-E43,"") | H43: EA | I43: 12.2 | J43: =E43*I43 -> 0
B44: Consignes | C44: Caisse 20bt vides consignées (Valser) | G44: =IF(D44-E44>0,D44-E44,"") | H44: EA | I44: 11 | J44: =E44*I44 -> 0
B45: Consignes | C45: Caisse verres consignés (Bières) | G45: =IF(D45-E45>0,D45-E45,"") | H45: EA | I45: 5 | J45: =E45*I45 -> 0
B46: Consignes | C46: Caisse BT 1,5L PET consignée | G46: =IF(D46-E46>0,D46-E46,"") | H46: EA | I46: 5 | J46: =E46*I46 -> 0
...

Sheet Nord Mobile 1
B1: TOTAL PRODUIT CONSOLIDE
B4: Catégories | C4: Valeur d'inventaire
B5: Bières | C5: =J23 -> 4286.5
B6: Consignes | C6: =J4 -> 0
B7: Vins | C7: =J50 -> 200.3
B8: Boissons avec alcool / Spiritueux | C8: =J78 -> 0
B9: Boissons sans alcool | C9: =J122 -> 534.26
B10: Caféterie | C10: =J176 -> 0
B11: Negoce | C11: =J187 -> 215.28
B12: Boulangerie | C12: =J193 -> 0
B13: Sauce & Condiments | C13: =J195 -> 0
B14: Surgelés | C14: =J208 -> 0
B15: Viandes | C15: =J214 -> 0
B16: Graisse & Huile | C16: =J222 -> 0
B17: Mono-usages | C17: =J224 -> 107.12
B18: Produit de nettoyage | C18: =J245 -> 10.9
B19: Divers | C19: =J257 -> 0
B20: TOTAL | C20: =C5+C6+C7+C8+C9+C10+C11+C12+C13+C14+C15+C16+C17+C18+C19 -> 5354.36
A21: INVENTAIRES STADE
B22: Catégorie | C22: Article d'inventaire | D22: MIN. REQUIS | E22: STOCKS FIN DE SERVICE | F22: QUANTITE A REMETTRE | G22: MANQUE / RUPTURE | H22: UNITE | I22: PRIX | J22: VALEUR
A23: Catégorie :Bières | E23: A REMPLIR ↓ | I23: TOTAL : | J23: =SUM(J24:J40) -> 4286.5
B24: Bières | C24: Aligal 2 7kg | D24: 2 | E24: 4 | G24: =IF(E24="","",IF(D24-E24>0,D24-E24,"")) | H24: EA | I24: 55.95 | J24: =E24*I24 -> 223.8
B25: Bières | C25: Brooklyn EIPA 30lt Fût | G25: =IF(E25="","",IF(D25-E25>0,D25-E25,"")) | H25: EA | I25: 173.1 | J25: =E25*I25 -> 0
B26: Bières | C26: Cardinal Blonde 20lt Fût | D26: 15 | E26: 46 | G26: =IF(E26="","",IF(D26-E26>0,D26-E26,"")) | H26: EA | I26: 75.4 | J26: =E26*I26 -> 3468.4
B27: Bières | C27: Servettienne 20lt Fût | D27: 15 | E27: 7 | G27: =IF(E27="","",IF(D27-E27>0,D27-E27,"")) -> 8 | H27: EA | I27: 84.9 | J27: =E27*I27 -> 594.3
B28: Bières | C28: Bonde la piece bouteille | G28: =IF(E28="","",IF(D28-E28>0,D28-E28,"")) | H28: EA | I28: 2.96 | J28: =E28*I28 -> 0
B29: Bières | C29: Blanche la piece bouteille | G29: =IF(E29="","",IF(D29-E29>0,D29-E29,"")) | H29: EA | I29: 2.96 | J29: =E29*I29 -> 0
B30: Bières | C30: IPA la piece bouteille | G30: =IF(E30="","",IF(D30-E30>0,D30-E30,"")) | H30: EA | I30: 2.96 | J30: =E30*I30 -> 0
B31: Bières | C31: Grimbergen blanche 20lt Fût | G31: =IF(E31="","",IF(D31-E31>0,D31-E31,"")) | H31: EA | I31: 107.2 | J31: =E31*I31 -> 0
B32: Bières | C32: Magners 30lt Fût | G32: =IF(E32="","",IF(D32-E32>0,D32-E32,"")) | H32: EA | I32: 170.7 | J32: =E32*I32 -> 0
B33: Bières | C33: Cardinal Blonde Citernes lt | G33: =IF(E33="","",IF(D33-E33>0,D33-E33,"")) | H33: lt | I33: 3.77 | J33: =E33*I33 -> 0
B34: Bières | C34: Valaisanne Bière de Cave - Bière bouteille | G34: =IF(E34="","",IF(D34-E34>0,D34-E34,"")) | H34: EA | I34: 2.56 | J34: =E34*I34 -> 0
B35: Bières | C35: Valaisanne IPA - Bière bouteille | G35: =IF(E35="","",IF(D35-E35>0,D35-E35,"")) | H35: EA | I35: 3.08 | J35: =E35*I35 -> 0
B36: Bières | C36: Valaisanne Pale Ale - Bière bouteille | G36: =IF(E36="","",IF(D36-E36>0,D36-E36,"")) | H36: EA | I36: 2.56 | J36: =E36*I36 -> 0
B37: Bières | C37: Cardinal - Bière bouteille | G37: =IF(E37="","",IF(D37-E37>0,D37-E37,"")) | H37: EA | I37: 1.41 | J37: =E37*I37 -> 0
B38: Bières | C38: San Miguel - Bière bouteille | G38: =IF(E38="","",IF(D38-E38>0,D38-E38,"")) | H38: EA | I38: 1.73 | J38: =E38*I38 -> 0
B39: Bières | C39: Cardinal sans alcool - Bière bouteille | G39: =IF(E39="","",IF(D39-E39>0,D39-E39,"")) | H39: EA | I39: 1.46 | J39: =E39*I39 -> 0
B40: Bières | C40: Cidre 33cl "La Genevoise du Terroir" | G40: =IF(E40="","",IF(D40-E40>0,D40-E40,"")) | H40: EA | I40: 3.45 | J40: =E40*I40 -> 0
A41: Catégorie : Consignes | G41: =IF(E41="","",IF(D41-E41>0,D41-E41,"")) | I41: TOTAL : | J41: =SUM(J42:J49) -> 3050
B42: Consignes | C42: Bouteille / Aligal consignée | E42: =E24 -> 4 | G42: =IF(E42="","",IF(D42-E42>0,D42-E42,"")) | H42: EA | I42: 100 | J42: =E42*I42 -> 400
...

Sheet Nord 1
B1: TOTAL PRODUIT CONSOLIDE
B4: Catégories | C4: Valeur d'inventaire
B5: Bières | C5: =J23 -> 5362.15
B6: Consignes | C6: =J4 -> 0
B7: Vins | C7: =J50 -> 132.5
B8: Boissons avec alcool / Spiritueux | C8: =J78 -> 0
B9: Boissons sans alcool | C9: =J122 -> 2047.79
B10: Caféterie | C10: =J176 -> 0
B11: Negoce | C11: =J187 -> 67.2
B12: Boulangerie | C12: =J193 -> 0
B13: Sauce & Condiments | C13: =J195 -> 168.61
B14: Surgelés | C14: =J208 -> 870.785
B15: Viandes | C15: =J214 -> 0
B16: Graisse & Huile | C16: =J222 -> 0
B17: Mono-usages | C17: =J224 -> 428.55
B18: Produit de nettoyage | C18: =J245 -> 238.97
B19: Divers | C19: =J257 -> 0
B20: TOTAL | C20: =C5+C6+C7+C8+C9+C10+C11+C12+C13+C14+C15+C16+C17+C18+C19 -> 9316.555
A21: INVENTAIRES STADE
B22: Catégorie | C22: Article d'inventaire | D22: MIN. REQUIS | E22: STOCKS FIN DE SERVICE | F22: QUANTITE A REMETTRE | G22: MANQUE / RUPTURE | H22: UNITE | I22: PRIX | J22: VALEUR
A23: Catégorie :Bières | E23: A REMPLIR ↓ | I23: TOTAL : | J23: =SUM(J24:J40) -> 5362.15
B24: Bières | C24: Aligal 2 7kg | D24: 2 | E24: 3 | G24: =IF(E24="","",IF(D24-E24>0,D24-E24,"")) | H24: EA | I24: 55.95 | J24: =E24*I24 -> 167.85
B25: Bières | C25: Brooklyn EIPA 30lt Fût | G25: =IF(E25="","",IF(D25-E25>0,D25-E25,"")) | H25: EA | I25: 173.1 | J25: =E25*I25 -> 0
B26: Bières | C26: Cardinal Blonde 20lt Fût | D26: 20 | E26: 52 | G26: =IF(E26="","",IF(D26-E26>0,D26-E26,"")) | H26: EA | I26: 75.4 | J26: =E26*I26 -> 3920.8
B27: Bières | C27: Servettienne 20lt Fût | D27: 20 | E27: 15 | G27: =IF(E27="","",IF(D27-E27>0,D27-E27,"")) -> 5 | H27: EA | I27: 84.9 | J27: =E27*I27 -> 1273.5
B28: Bières | C28: Bonde la piece bouteille | G28: =IF(E28="","",IF(D28-E28>0,D28-E28,"")) | H28: EA | I28: 2.96 | J28: =E28*I28 -> 0
B29: Bières | C29: Blanche la piece bouteille | G29: =IF(E29="","",IF(D29-E29>0,D29-E29,"")) | H29: EA | I29: 2.96 | J29: =E29*I29 -> 0
B30: Bières | C30: IPA la piece bouteille | G30: =IF(E30="","",IF(D30-E30>0,D30-E30,"")) | H30: EA | I30: 2.96 | J30: =E30*I30 -> 0
B31: Bières | C31: Grimbergen blanche 20lt Fût | G31: =IF(E31="","",IF(D31-E31>0,D31-E31,"")) | H31: EA | I31: 107.2 | J31: =E31*I31 -> 0
B32: Bières | C32: Magners 30lt Fût | G32: =IF(E32="","",IF(D32-E32>0,D32-E32,"")) | H32: EA | I32: 170.7 | J32: =E32*I32 -> 0
B33: Bières | C33: Cardinal Blonde Citernes lt | G33: =IF(E33="","",IF(D33-E33>0,D33-E33,"")) | H33: lt | I33: 3.77 | J33: =E33*I33 -> 0
B34: Bières | C34: Valaisanne Bière de Cave - Bière bouteille | G34: =IF(E34="","",IF(D34-E34>0,D34-E34,"")) | H34: EA | I34: 2.56 | J34: =E34*I34 -> 0
B35: Bières | C35: Valaisanne IPA - Bière bouteille | G35: =IF(E35="","",IF(D35-E35>0,D35-E35,"")) | H35: EA | I35: 3.08 | J35: =E35*I35 -> 0
B36: Bières | C36: Valaisanne Pale Ale - Bière bouteille | G36: =IF(E36="","",IF(D36-E36>0,D36-E36,"")) | H36: EA | I36: 2.56 | J36: =E36*I36 -> 0
B37: Bières | C37: Cardinal - Bière bouteille | G37: =IF(E37="","",IF(D37-E37>0,D37-E37,"")) | H37: EA | I37: 1.41 | J37: =E37*I37 -> 0
B38: Bières | C38: San Miguel - Bière bouteille | G38: =IF(E38="","",IF(D38-E38>0,D38-E38,"")) | H38: EA | I38: 1.73 | J38: =E38*I38 -> 0
B39: Bières | C39: Cardinal sans alcool - Bière bouteille | G39: =IF(E39="","",IF(D39-E39>0,D39-E39,"")) | H39: EA | I39: 1.46 | J39: =E39*I39 -> 0
B40: Bières | C40: Cidre 33cl "La Genevoise du Terroir" | G40: =IF(E40="","",IF(D40-E40>0,D40-E40,"")) | H40: EA | I40: 3.45 | J40: =E40*I40 -> 0
A41: Catégorie : Consignes | G41: =IF(E41="","",IF(D41-E41>0,D41-E41,"")) | I41: TOTAL : | J41: =SUM(J42:J49) -> 3690
B42: Consignes | C42: Bouteille / Aligal consignée | E42: =E24 -> 3 | G42: =IF(E42="","",IF(D42-E42>0,D42-E42,"")) | H42: EA | I42: 100 | J42: =E42*I42 -> 300
...

Sheet Nord 2
B1: TOTAL PRODUIT CONSOLIDE
B4: Catégories | C4: Valeur d'inventaire
B5: Bières | C5: =J23 -> 4615.25
B6: Consignes | C6: =J4 -> 0
B7: Vins | C7: =J50 -> 79
B8: Boissons avec alcool / Spiritueux | C8: =J78 -> 0
B9: Boissons sans alcool | C9: =J122 -> 3584.54
B10: Caféterie | C10: =J176 -> 0
B11: Negoce | C11: =J187 -> 76.8
B12: Boulangerie | C12: =J193 -> 0
B13: Sauce & Condiments | C13: =J195 -> 236.57
B14: Surgelés | C14: =J208 -> 2160.47
B15: Viandes | C15: =J214 -> 0
B16: Graisse & Huile | C16: =J222 -> 208
B17: Mono-usages | C17: =J224 -> 521.92
B18: Produit de nettoyage | C18: =J245 -> 226.24
B19: Divers | C19: =J257 -> 0
B20: TOTAL | C20: =C5+C6+C7+C8+C9+C10+C11+C12+C13+C14+C15+C16+C17+C18+C19 -> 11708.79
A21: INVENTAIRES STADE
B22: Catégorie | C22: Article d'inventaire | D22: MIN. REQUIS | E22: STOCKS FIN DE SERVICE | F22: QUANTITE A REMETTRE | G22: MANQUE / RUPTURE | H22: UNITE | I22: PRIX | J22: VALEUR
A23: Catégorie :Bières | E23: A REMPLIR ↓ | I23: TOTAL : | J23: =SUM(J24:J40) -> 4615.25
B24: Bières | C24: Aligal 2 7kg | D24: 2 | E24: 7 | G24: =IF(E24="","",IF(D24-E24>0,D24-E24,"")) | H24: EA | I24: 55.95 | J24: =E24*I24 -> 391.65
B25: Bières | C25: Brooklyn EIPA 30lt Fût | G25: =IF(E25="","",IF(D25-E25>0,D25-E25,"")) | H25: EA | I25: 173.1 | J25: =E25*I25 -> 0
B26: Bières | C26: Cardinal Blonde 20lt Fût | D26: 20 | E26: 38 | G26: =IF(E26="","",IF(D26-E26>0,D26-E26,"")) | H26: EA | I26: 75.4 | J26: =E26*I26 -> 2865.2
B27: Bières | C27: Servettienne 20lt Fût | D27: 20 | E27: 16 | G27: =IF(E27="","",IF(D27-E27>0,D27-E27,"")) -> 4 | H27: EA | I27: 84.9 | J27: =E27*I27 -> 1358.4
B28: Bières | C28: Bonde la piece bouteille | G28: =IF(E28="","",IF(D28-E28>0,D28-E28,"")) | H28: EA | I28: 2.96 | J28: =E28*I28 -> 0
B29: Bières | C29: Blanche la piece bouteille | G29: =IF(E29="","",IF(D29-E29>0,D29-E29,"")) | H29: EA | I29: 2.96 | J29: =E29*I29 -> 0
B30: Bières | C30: IPA la piece bouteille | G30: =IF(E30="","",IF(D30-E30>0,D30-E30,"")) | H30: EA | I30: 2.96 | J30: =E30*I30 -> 0
B31: Bières | C31: Grimbergen blanche 20lt Fût | G31: =IF(E31="","",IF(D31-E31>0,D31-E31,"")) | H31: EA | I31: 107.2 | J31: =E31*I31 -> 0
B32: Bières | C32: Magners 30lt Fût | G32: =IF(E32="","",IF(D32-E32>0,D32-E32,"")) | H32: EA | I32: 170.7 | J32: =E32*I32 -> 0
B33: Bières | C33: Cardinal Blonde Citernes lt | G33: =IF(E33="","",IF(D33-E33>0,D33-E33,"")) | H33: lt | I33: 3.77 | J33: =E33*I33 -> 0
B34: Bières | C34: Valaisanne Bière de Cave - Bière bouteille | G34: =IF(E34="","",IF(D34-E34>0,D34-E34,"")) | H34: EA | I34: 2.56 | J34: =E34*I34 -> 0
B35: Bières | C35: Valaisanne IPA - Bière bouteille | G35: =IF(E35="","",IF(D35-E35>0,D35-E35,"")) | H35: EA | I35: 3.08 | J35: =E35*I35 -> 0
B36: Bières | C36: Valaisanne Pale Ale - Bière bouteille | G36: =IF(E36="","",IF(D36-E36>0,D36-E36,"")) | H36: EA | I36: 2.56 | J36: =E36*I36 -> 0
B37: Bières | C37: Cardinal - Bière bouteille | G37: =IF(E37="","",IF(D37-E37>0,D37-E37,"")) | H37: EA | I37: 1.41 | J37: =E37*I37 -> 0
B38: Bières | C38: San Miguel - Bière bouteille | G38: =IF(E38="","",IF(D38-E38>0,D38-E38,"")) | H38: EA | I38: 1.73 | J38: =E38*I38 -> 0
B39: Bières | C39: Cardinal sans alcool - Bière bouteille | G39: =IF(E39="","",IF(D39-E39>0,D39-E39,"")) | H39: EA | I39: 1.46 | J39: =E39*I39 -> 0
B40: Bières | C40: Cidre 33cl "La Genevoise du Terroir" | G40: =IF(E40="","",IF(D40-E40>0,D40-E40,"")) | H40: EA | I40: 3.45 | J40: =E40*I40 -> 0
A41: Catégorie : Consignes | G41: =IF(E41="","",IF(D41-E41>0,D41-E41,"")) | I41: TOTAL : | J41: =SUM(J42:J49) -> 3570
B42: Consignes | C42: Bouteille / Aligal consignée | E42: =E24 -> 7 | G42: =IF(E42="","",IF(D42-E42>0,D42-E42,"")) | H42: EA | I42: 100 | J42: =E42*I42 -> 700
...

Sheet Nord Mobile 2
B1: TOTAL PRODUIT CONSOLIDE
B4: Catégories | C4: Valeur d'inventaire
B5: Bières | C5: =J23 -> 4239.75
B6: Consignes | C6: =J4 -> 0
B7: Vins | C7: =J50 -> 139.1
B8: Boissons avec alcool / Spiritueux | C8: =J78 -> 0
B9: Boissons sans alcool | C9: =J122 -> 668.68
B10: Caféterie | C10: =J176 -> 0
B11: Negoce | C11: =J187 -> 0
B12: Boulangerie | C12: =J193 -> 0
B13: Sauce & Condiments | C13: =J195 -> 0
B14: Surgelés | C14: =J208 -> 0
B15: Viandes | C15: =J214 -> 0
B16: Graisse & Huile | C16: =J222 -> 0
B17: Mono-usages | C17: =J224 -> 0
B18: Produit de nettoyage | C18: =J245 -> 7.2
B19: Divers | C19: =J257 -> 0
B20: TOTAL | C20: =C5+C6+C7+C8+C9+C10+C11+C12+C13+C14+C15+C16+C17+C18+C19 -> 5054.73
A21: INVENTAIRES STADE
B22: Catégorie | C22: Article d'inventaire | D22: MIN. REQUIS | E22: STOCKS FIN DE SERVICE | F22: QUANTITE A REMETTRE | G22: MANQUE / RUPTURE | H22: UNITE | I22: PRIX | J22: VALEUR
A23: Catégorie :Bières | E23: A REMPLIR ↓ | I23: TOTAL : | J23: =SUM(J24:J40) -> 4239.75
B24: Bières | C24: Aligal 2 7kg | D24: 2 | E24: 5 | G24: =IF(E24="","",IF(D24-E24>0,D24-E24,"")) | H24: EA | I24: 55.95 | J24: =E24*I24 -> 279.75
B25: Bières | C25: Brooklyn EIPA 30lt Fût | G25: =IF(E25="","",IF(D25-E25>0,D25-E25,"")) | H25: EA | I25: 173.1 | J25: =E25*I25 -> 0
B26: Bières | C26: Cardinal Blonde 20lt Fût | D26: 15 | E26: 30 | G26: =IF(E26="","",IF(D26-E26>0,D26-E26,"")) | H26: EA | I26: 75.4 | J26: =E26*I26 -> 2262
B27: Bières | C27: Servettienne 20lt Fût | D27: 15 | E27: 20 | G27: =IF(E27="","",IF(D27-E27>0,D27-E27,"")) | H27: EA | I27: 84.9 | J27: =E27*I27 -> 1698
B28: Bières | C28: Bonde la piece bouteille | G28: =IF(E28="","",IF(D28-E28>0,D28-E28,"")) | H28: EA | I28: 2.96 | J28: =E28*I28 -> 0
B29: Bières | C29: Blanche la piece bouteille | G29: =IF(E29="","",IF(D29-E29>0,D29-E29,"")) | H29: EA | I29: 2.96 | J29: =E29*I29 -> 0
B30: Bières | C30: IPA la piece bouteille | G30: =IF(E30="","",IF(D30-E30>0,D30-E30,"")) | H30: EA | I30: 2.96 | J30: =E30*I30 -> 0
B31: Bières | C31: Grimbergen blanche 20lt Fût | G31: =IF(E31="","",IF(D31-E31>0,D31-E31,"")) | H31: EA | I31: 107.2 | J31: =E31*I31 -> 0
B32: Bières | C32: Magners 30lt Fût | G32: =IF(E32="","",IF(D32-E32>0,D32-E32,"")) | H32: EA | I32: 170.7 | J32: =E32*I32 -> 0
B33: Bières | C33: Cardinal Blonde Citernes lt | G33: =IF(E33="","",IF(D33-E33>0,D33-E33,"")) | H33: lt | I33: 3.77 | J33: =E33*I33 -> 0
B34: Bières | C34: Valaisanne Bière de Cave - Bière bouteille | G34: =IF(E34="","",IF(D34-E34>0,D34-E34,"")) | H34: EA | I34: 2.56 | J34: =E34*I34 -> 0
B35: Bières | C35: Valaisanne IPA - Bière bouteille | G35: =IF(E35="","",IF(D35-E35>0,D35-E35,"")) | H35: EA | I35: 3.08 | J35: =E35*I35 -> 0
B36: Bières | C36: Valaisanne Pale Ale - Bière bouteille | G36: =IF(E36="","",IF(D36-E36>0,D36-E36,"")) | H36: EA | I36: 2.56 | J36: =E36*I36 -> 0
B37: Bières | C37: Cardinal - Bière bouteille | G37: =IF(E37="","",IF(D37-E37>0,D37-E37,"")) | H37: EA | I37: 1.41 | J37: =E37*I37 -> 0
B38: Bières | C38: San Miguel - Bière bouteille | G38: =IF(E38="","",IF(D38-E38>0,D38-E38,"")) | H38: EA | I38: 1.73 | J38: =E38*I38 -> 0
B39: Bières | C39: Cardinal sans alcool - Bière bouteille | G39: =IF(E39="","",IF(D39-E39>0,D39-E39,"")) | H39: EA | I39: 1.46 | J39: =E39*I39 -> 0
B40: Bières | C40: Cidre 33cl "La Genevoise du Terroir" | G40: =IF(E40="","",IF(D40-E40>0,D40-E40,"")) | H40: EA | I40: 3.45 | J40: =E40*I40 -> 0
A41: Catégorie : Consignes | G41: =IF(E41="","",IF(D41-E41>0,D41-E41,"")) | I41: TOTAL : | J41: =SUM(J42:J49) -> 3020
B42: Consignes | C42: Bouteille / Aligal consignée | E42: =E24 -> 5 | G42: =IF(E42="","",IF(D42-E42>0,D42-E42,"")) | H42: EA | I42: 100 | J42: =E42*I42 -> 500
...

Sheet Esplanade
B1: TOTAL PRODUIT CONSOLIDE
B4: Catégories | C4: Valeur d'inventaire
B5: Bières | C5: =J23 -> 5351.4
B6: Consignes | C6: =J4 -> 0
B7: Vins | C7: =J50 -> 43.4
B8: Boissons avec alcool / Spiritueux | C8: =J78 -> 0
B9: Boissons sans alcool | C9: =J122 -> 289.64
B10: Caféterie | C10: =J176 -> 0
B11: Negoce | C11: =J187 -> 0
B12: Boulangerie | C12: =J193 -> 0
B13: Sauce & Condiments | C13: =J195 -> 0
B14: Surgelés | C14: =J208 -> 0
B15: Viandes | C15: =J214 -> 0
B16: Graisse & Huile | C16: =J222 -> 0
B17: Mono-usages | C17: =J224 -> 0
B18: Produit de nettoyage | C18: =J245 -> 30.7
B19: Divers | C19: =J257 -> 0
B20: TOTAL | C20: =C5+C6+C7+C8+C9+C10+C11+C12+C13+C14+C15+C16+C17+C18+C19 -> 5715.14
A21: INVENTAIRES STADE
B22: Catégorie | C22: Article d'inventaire | D22: MIN. REQUIS | E22: STOCKS FIN DE SERVICE | F22: QUANTITE A REMETTRE | G22: MANQUE / RUPTURE | H22: UNITE | I22: PRIX | J22: VALEUR
A23: Catégorie :Bières | E23: A REMPLIR ↓ | I23: TOTAL : | J23: =SUM(J24:J40) -> 5351.4
B24: Bières | C24: Aligal 2 7kg | E24: 4 | G24: =IF(E24="","",IF(D24-E24>0,D24-E24,"")) | H24: EA | I24: 55.95 | J24: =E24*I24 -> 223.8
B25: Bières | C25: Brooklyn EIPA 30lt Fût | G25: =IF(E25="","",IF(D25-E25>0,D25-E25,"")) | H25: EA | I25: 173.1 | J25: =E25*I25 -> 0
B26: Bières | C26: Cardinal Blonde 20lt Fût | E26: 3 | G26: =IF(E26="","",IF(D26-E26>0,D26-E26,"")) | H26: EA | I26: 75.4 | J26: =E26*I26 -> 226.2
B27: Bières | C27: Servettienne 20lt Fût | E27: 4 | G27: =IF(E27="","",IF(D27-E27>0,D27-E27,"")) | H27: EA | I27: 84.9 | J27: =E27*I27 -> 339.6
B28: Bières | C28: Bonde la piece bouteille | G28: =IF(E28="","",IF(D28-E28>0,D28-E28,"")) | H28: EA | I28: 2.96 | J28: =E28*I28 -> 0
B29: Bières | C29: Blanche la piece bouteille | G29: =IF(E29="","",IF(D29-E29>0,D29-E29,"")) | H29: EA | I29: 2.96 | J29: =E29*I29 -> 0
B30: Bières | C30: IPA la piece bouteille | G30: =IF(E30="","",IF(D30-E30>0,D30-E30,"")) | H30: EA | I30: 2.96 | J30: =E30*I30 -> 0
B31: Bières | C31: Grimbergen blanche 20lt Fût | E31: 33 | G31: =IF(E31="","",IF(D31-E31>0,D31-E31,"")) | H31: EA | I31: 107.2 | J31: =E31*I31 -> 3537.6
B32: Bières | C32: Magners 30lt Fût | E32: 6 | G32: =IF(E32="","",IF(D32-E32>0,D32-E32,"")) | H32: EA | I32: 170.7 | J32: =E32*I32 -> 1024.2
B33: Bières | C33: Cardinal Blonde Citernes lt | G33: =IF(E33="","",IF(D33-E33>0,D33-E33,"")) | H33: lt | I33: 3.77 | J33: =E33*I33 -> 0
B34: Bières | C34: Valaisanne Bière de Cave - Bière bouteille | G34: =IF(E34="","",IF(D34-E34>0,D34-E34,"")) | H34: EA | I34: 2.56 | J34: =E34*I34 -> 0
B35: Bières | C35: Valaisanne IPA - Bière bouteille | G35: =IF(E35="","",IF(D35-E35>0,D35-E35,"")) | H35: EA | I35: 3.08 | J35: =E35*I35 -> 0
B36: Bières | C36: Valaisanne Pale Ale - Bière bouteille | G36: =IF(E36="","",IF(D36-E36>0,D36-E36,"")) | H36: EA | I36: 2.56 | J36: =E36*I36 -> 0
B37: Bières | C37: Cardinal - Bière bouteille | G37: =IF(E37="","",IF(D37-E37>0,D37-E37,"")) | H37: EA | I37: 1.41 | J37: =E37*I37 -> 0
B38: Bières | C38: San Miguel - Bière bouteille | G38: =IF(E38="","",IF(D38-E38>0,D38-E38,"")) | H38: EA | I38: 1.73 | J38: =E38*I38 -> 0
B39: Bières | C39: Cardinal sans alcool - Bière bouteille | G39: =IF(E39="","",IF(D39-E39>0,D39-E39,"")) | H39: EA | I39: 1.46 | J39: =E39*I39 -> 0
B40: Bières | C40: Cidre 33cl "La Genevoise du Terroir" | G40: =IF(E40="","",IF(D40-E40>0,D40-E40,"")) | H40: EA | I40: 3.45 | J40: =E40*I40 -> 0
A41: Catégorie : Consignes | G41: =IF(E41="","",IF(D41-E41>0,D41-E41,"")) | I41: TOTAL : | J41: =SUM(J42:J49) -> 2480
B42: Consignes | C42: Bouteille / Aligal consignée | G42: =IF(E42="","",IF(D42-E42>0,D42-E42,"")) | H42: EA | I42: 100 | J42: =E42*I42 -> 0
...

Sheet Est mobile 1
B1: TOTAL PRODUIT CONSOLIDE
B4: Catégories | C4: Valeur d'inventaire
B5: Bières | C5: =J23 -> 3046.3
B6: Consignes | C6: =J4 -> 0
B7: Vins | C7: =J50 -> 318.85
B8: Boissons avec alcool / Spiritueux | C8: =J78 -> 0
B9: Boissons sans alcool | C9: =J122 -> 122.56
B10: Caféterie | C10: =J176 -> 0
B11: Negoce | C11: =J187 -> 0
B12: Boulangerie | C12: =J193 -> 0
B13: Sauce & Condiments | C13: =J195 -> 0
B14: Surgelés | C14: =J208 -> 0
B15: Viandes | C15: =J214 -> 0
B16: Graisse & Huile | C16: =J222 -> 0
B17: Mono-usages | C17: =J224 -> 55.735
B18: Produit de nettoyage | C18: =J245 -> 13.35
B19: Divers | C19: =J257 -> 0
B20: TOTAL | C20: =C5+C6+C7+C8+C9+C10+C11+C12+C13+C14+C15+C16+C17+C18+C19 -> 3556.795
A21: INVENTAIRES STADE
B22: Catégorie | C22: Article d'inventaire | D22: MIN. REQUIS | E22: STOCKS FIN DE SERVICE | F22: QUANTITE A REMETTRE | G22: MANQUE / RUPTURE | H22: UNITE | I22: PRIX | J22: VALEUR
A23: Catégorie :Bières | E23: A REMPLIR ↓ | I23: TOTAL : | J23: =SUM(J24:J40) -> 3046.3
B24: Bières | C24: Aligal 2 7kg | D24: 2 | G24: =IF(E24="","",IF(D24-E24>0,D24-E24,"")) | H24: EA | I24: 55.95 | J24: =E24*I24 -> 0
B25: Bières | C25: Brooklyn EIPA 30lt Fût | G25: =IF(E25="","",IF(D25-E25>0,D25-E25,"")) | H25: EA | I25: 173.1 | J25: =E25*I25 -> 0
B26: Bières | C26: Cardinal Blonde 20lt Fût | D26: 15 | E26: 10 | G26: =IF(E26="","",IF(D26-E26>0,D26-E26,"")) -> 5 | H26: EA | I26: 75.4 | J26: =E26*I26 -> 754
B27: Bières | C27: Servettienne 20lt Fût | D27: 15 | E27: 27 | G27: =IF(E27="","",IF(D27-E27>0,D27-E27,"")) | H27: EA | I27: 84.9 | J27: =E27*I27 -> 2292.3
B28: Bières | C28: Bonde la piece bouteille | G28: =IF(E28="","",IF(D28-E28>0,D28-E28,"")) | H28: EA | I28: 2.96 | J28: =E28*I28 -> 0
B29: Bières | C29: Blanche la piece bouteille | G29: =IF(E29="","",IF(D29-E29>0,D29-E29,"")) | H29: EA | I29: 2.96 | J29: =E29*I29 -> 0
B30: Bières | C30: IPA la piece bouteille | G30: =IF(E30="","",IF(D30-E30>0,D30-E30,"")) | H30: EA | I30: 2.96 | J30: =E30*I30 -> 0
B31: Bières | C31: Grimbergen blanche 20lt Fût | G31: =IF(E31="","",IF(D31-E31>0,D31-E31,"")) | H31: EA | I31: 107.2 | J31: =E31*I31 -> 0
B32: Bières | C32: Magners 30lt Fût | G32: =IF(E32="","",IF(D32-E32>0,D32-E32,"")) | H32: EA | I32: 170.7 | J32: =E32*I32 -> 0
B33: Bières | C33: Cardinal Blonde Citernes lt | G33: =IF(E33="","",IF(D33-E33>0,D33-E33,"")) | H33: lt | I33: 3.77 | J33: =E33*I33 -> 0
B34: Bières | C34: Valaisanne Bière de Cave - Bière bouteille | G34: =IF(E34="","",IF(D34-E34>0,D34-E34,"")) | H34: EA | I34: 2.56 | J34: =E34*I34 -> 0
B35: Bières | C35: Valaisanne IPA - Bière bouteille | G35: =IF(E35="","",IF(D35-E35>0,D35-E35,"")) | H35: EA | I35: 3.08 | J35: =E35*I35 -> 0
B36: Bières | C36: Valaisanne Pale Ale - Bière bouteille | G36: =IF(E36="","",IF(D36-E36>0,D36-E36,"")) | H36: EA | I36: 2.56 | J36: =E36*I36 -> 0
B37: Bières | C37: Cardinal - Bière bouteille | G37: =IF(E37="","",IF(D37-E37>0,D37-E37,"")) | H37: EA | I37: 1.41 | J37: =E37*I37 -> 0
B38: Bières | C38: San Miguel - Bière bouteille | G38: =IF(E38="","",IF(D38-E38>0,D38-E38,"")) | H38: EA | I38: 1.73 | J38: =E38*I38 -> 0
B39: Bières | C39: Cardinal sans alcool - Bière bouteille | G39: =IF(E39="","",IF(D39-E39>0,D39-E39,"")) | H39: EA | I39: 1.46 | J39: =E39*I39 -> 0
B40: Bières | C40: Cidre 33cl "La Genevoise du Terroir" | G40: =IF(E40="","",IF(D40-E40>0,D40-E40,"")) | H40: EA | I40: 3.45 | J40: =E40*I40 -> 0
A41: Catégorie : Consignes | G41: =IF(E41="","",IF(D41-E41>0,D41-E41,"")) | I41: TOTAL : | J41: =SUM(J42:J49) -> 1875
B42: Consignes | C42: Bouteille / Aligal consignée | E42: =E24 -> 0 | G42: =IF(E42="","",IF(D42-E42>0,D42-E42,"")) | H42: EA | I42: 100 | J42: =E42*I42 -> 0
...

Sheet Est 1
B1: TOTAL PRODUIT CONSOLIDE
B4: Catégories | C4: Valeur d'inventaire
B5: Bières | C5: =J23 -> 4967.2
B6: Consignes | C6: =J4 -> 0
B7: Vins | C7: =J50 -> 138.35
B8: Boissons avec alcool / Spiritueux | C8: =J78 -> 0
B9: Boissons sans alcool | C9: =J122 -> 2145.31
B10: Caféterie | C10: =J176 -> 0
B11: Negoce | C11: =J187 -> 331.2
B12: Boulangerie | C12: =J193 -> 0
B13: Sauce & Condiments | C13: =J195 -> 0
B14: Surgelés | C14: =J208 -> 755.79
B15: Viandes | C15: =J214 -> 0
B16: Graisse & Huile | C16: =J222 -> 0
B17: Mono-usages | C17: =J224 -> 0
B18: Produit de nettoyage | C18: =J245 -> 0
B19: Divers | C19: =J257 -> 0
B20: TOTAL | C20: =C5+C6+C7+C8+C9+C10+C11+C12+C13+C14+C15+C16+C17+C18+C19 -> 8337.85
A21: INVENTAIRES STADE
B22: Catégorie | C22: Article d'inventaire | D22: MIN. REQUIS | E22: STOCKS FIN DE SERVICE | F22: QUANTITE A REMETTRE | G22: MANQUE / RUPTURE | H22: UNITE | I22: PRIX | J22: VALEUR
A23: Catégorie :Bières | E23: A REMPLIR ↓ | I23: TOTAL : | J23: =SUM(J24:J40) -> 4967.2
B24: Bières | C24: Aligal 2 7kg | D24: 2 | E24: 2 | G24: =IF(E199="",D199,IF(D199-E199>0,D199-E199,0)) -> 3 | H24: EA | I24: 55.95 | J24: =E24*I24 -> 111.9
B25: Bières | C25: Brooklyn EIPA 30lt Fût | G25: =IF(E25="",D25,IF(D25-E25>0,D25-E25,"")) -> 0 | H25: EA | I25: 173.1 | J25: =E25*I25 -> 0
B26: Bières | C26: Cardinal Blonde 20lt Fût | D26: 20 | E26: 43 | G26: =IF(E26="",D26,IF(D26-E26>0,D26-E26,"")) | H26: EA | I26: 75.4 | J26: =E26*I26 -> 3242.2
B27: Bières | C27: Servettienne 20lt Fût | D27: 20 | E27: 19 | G27: =IF(E27="",D27,IF(D27-E27>0,D27-E27,"")) -> 1 | H27: EA | I27: 84.9 | J27: =E27*I27 -> 1613.1
B28: Bières | C28: Bonde la piece bouteille | G28: =IF(E28="",D28,IF(D28-E28>0,D28-E28,"")) -> 0 | H28: EA | I28: 2.96 | J28: =E28*I28 -> 0
B29: Bières | C29: Blanche la piece bouteille | G29: =IF(E29="",D29,IF(D29-E29>0,D29-E29,"")) -> 0 | H29: EA | I29: 2.96 | J29: =E29*I29 -> 0
B30: Bières | C30: IPA la piece bouteille | G30: =IF(E30="",D30,IF(D30-E30>0,D30-E30,"")) -> 0 | H30: EA | I30: 2.96 | J30: =E30*I30 -> 0
B31: Bières | C31: Grimbergen blanche 20lt Fût | G31: =IF(E31="",D31,IF(D31-E31>0,D31-E31,"")) -> 0 | H31: EA | I31: 107.2 | J31: =E31*I31 -> 0
B32: Bières | C32: Magners 30lt Fût | G32: =IF(E32="",D32,IF(D32-E32>0,D32-E32,"")) -> 0 | H32: EA | I32: 170.7 | J32: =E32*I32 -> 0
B33: Bières | C33: Cardinal Blonde Citernes lt | G33: =IF(E33="",D33,IF(D33-E33>0,D33-E33,"")) -> 0 | H33: lt | I33: 3.77 | J33: =E33*I33 -> 0
B34: Bières | C34: Valaisanne Bière de Cave - Bière bouteille | G34: =IF(E34="",D34,IF(D34-E34>0,D34-E34,"")) -> 0 | H34: EA | I34: 2.56 | J34: =E34*I34 -> 0
B35: Bières | C35: Valaisanne IPA - Bière bouteille | G35: =IF(E35="",D35,IF(D35-E35>0,D35-E35,"")) -> 0 | H35: EA | I35: 3.08 | J35: =E35*I35 -> 0
B36: Bières | C36: Valaisanne Pale Ale - Bière bouteille | G36: =IF(E36="",D36,IF(D36-E36>0,D36-E36,"")) -> 0 | H36: EA | I36: 2.56 | J36: =E36*I36 -> 0
B37: Bières | C37: Cardinal - Bière bouteille | G37: =IF(E37="",D37,IF(D37-E37>0,D37-E37,"")) -> 0 | H37: EA | I37: 1.41 | J37: =E37*I37 -> 0
B38: Bières | C38: San Miguel - Bière bouteille | G38: =IF(E38="",D38,IF(D38-E38>0,D38-E38,"")) -> 0 | H38: EA | I38: 1.73 | J38: =E38*I38 -> 0
B39: Bières | C39: Cardinal sans alcool - Bière bouteille | G39: =IF(E39="",D39,IF(D39-E39>0,D39-E39,"")) -> 0 | H39: EA | I39: 1.46 | J39: =E39*I39 -> 0
B40: Bières | C40: Cidre 33cl "La Genevoise du Terroir" | G40: =IF(E40="",D40,IF(D40-E40>0,D40-E40,"")) -> 0 | H40: EA | I40: 3.45 | J40: =E40*I40 -> 0
A41: Catégorie : Consignes | G41: =IF(E41="",D41,IF(D41-E41>0,D41-E41,"")) -> 0 | I41: TOTAL : | J41: =SUM(J42:J49) -> 3300
B42: Consignes | C42: Bouteille / Aligal consignée | E42: =E24 -> 2 | G42: =IF(E42="",D42,IF(D42-E42>0,D42-E42,"")) | H42: EA | I42: 100 | J42: =E42*I42 -> 200
...

Sheet Est mobile 2
B1: TOTAL PRODUIT CONSOLIDE
B4: Catégories | C4: Valeur d'inventaire
B5: Bières | C5: =J23 -> 4751.55
B6: Consignes | C6: =J4 -> 0
B7: Vins | C7: =J50 -> 124.05
B8: Boissons avec alcool / Spiritueux | C8: =J78 -> 0
B9: Boissons sans alcool | C9: =J122 -> 103.42
B10: Caféterie | C10: =J176 -> 0
B11: Negoce | C11: =J187 -> 0
B12: Boulangerie | C12: =J193 -> 0
B13: Sauce & Condiments | C13: =J195 -> 0
B14: Surgelés | C14: =J208 -> 0
B15: Viandes | C15: =J214 -> 0
B16: Graisse & Huile | C16: =J222 -> 0
B17: Mono-usages | C17: =J224 -> 0
B18: Produit de nettoyage | C18: =J245 -> 29.85
B19: Divers | C19: =J257 -> 0
B20: TOTAL | C20: =C5+C6+C7+C8+C9+C10+C11+C12+C13+C14+C15+C16+C17+C18+C19 -> 5008.87
A21: INVENTAIRES STADE
B22: Catégorie | C22: Article d'inventaire | D22: MIN. REQUIS | E22: STOCKS FIN DE SERVICE | F22: QUANTITE A REMETTRE | G22: MANQUE / RUPTURE | H22: UNITE | I22: PRIX | J22: VALEUR
A23: Catégorie :Bières | E23: A REMPLIR ↓ | I23: TOTAL : | J23: =SUM(J24:J40) -> 4751.55
B24: Bières | C24: Aligal 2 7kg | D24: 2 | E24: 1 | G24: =IF(E24="","",IF(D24-E24>0,D24-E24,"")) -> 1 | H24: EA | I24: 55.95 | J24: =E24*I24 -> 55.95
B25: Bières | C25: Brooklyn EIPA 30lt Fût | G25: =IF(E25="","",IF(D25-E25>0,D25-E25,"")) | H25: EA | I25: 173.1 | J25: =E25*I25 -> 0
B26: Bières | C26: Cardinal Blonde 20lt Fût | D26: 15 | E26: 33 | G26: =IF(E26="","",IF(D26-E26>0,D26-E26,"")) | H26: EA | I26: 75.4 | J26: =E26*I26 -> 2488.2
B27: Bières | C27: Servettienne 20lt Fût | D27: 15 | E27: 26 | G27: =IF(E27="","",IF(D27-E27>0,D27-E27,"")) | H27: EA | I27: 84.9 | J27: =E27*I27 -> 2207.4
B28: Bières | C28: Bonde la piece bouteille | G28: =IF(E28="","",IF(D28-E28>0,D28-E28,"")) | H28: EA | I28: 2.96 | J28: =E28*I28 -> 0
B29: Bières | C29: Blanche la piece bouteille | G29: =IF(E29="","",IF(D29-E29>0,D29-E29,"")) | H29: EA | I29: 2.96 | J29: =E29*I29 -> 0
B30: Bières | C30: IPA la piece bouteille | G30: =IF(E30="","",IF(D30-E30>0,D30-E30,"")) | H30: EA | I30: 2.96 | J30: =E30*I30 -> 0
B31: Bières | C31: Grimbergen blanche 20lt Fût | G31: =IF(E31="","",IF(D31-E31>0,D31-E31,"")) | H31: EA | I31: 107.2 | J31: =E31*I31 -> 0
B32: Bières | C32: Magners 30lt Fût | G32: =IF(E32="","",IF(D32-E32>0,D32-E32,"")) | H32: EA | I32: 170.7 | J32: =E32*I32 -> 0
B33: Bières | C33: Cardinal Blonde Citernes lt | G33: =IF(E33="","",IF(D33-E33>0,D33-E33,"")) | H33: lt | I33: 3.77 | J33: =E33*I33 -> 0
B34: Bières | C34: Valaisanne Bière de Cave - Bière bouteille | G34: =IF(E34="","",IF(D34-E34>0,D34-E34,"")) | H34: EA | I34: 2.56 | J34: =E34*I34 -> 0
B35: Bières | C35: Valaisanne IPA - Bière bouteille | G35: =IF(E35="","",IF(D35-E35>0,D35-E35,"")) | H35: EA | I35: 3.08 | J35: =E35*I35 -> 0
B36: Bières | C36: Valaisanne Pale Ale - Bière bouteille | G36: =IF(E36="","",IF(D36-E36>0,D36-E36,"")) | H36: EA | I36: 2.56 | J36: =E36*I36 -> 0
B37: Bières | C37: Cardinal - Bière bouteille | G37: =IF(E37="","",IF(D37-E37>0,D37-E37,"")) | H37: EA | I37: 1.41 | J37: =E37*I37 -> 0
B38: Bières | C38: San Miguel - Bière bouteille | G38: =IF(E38="","",IF(D38-E38>0,D38-E38,"")) | H38: EA | I38: 1.73 | J38: =E38*I38 -> 0
B39: Bières | C39: Cardinal sans alcool - Bière bouteille | G39: =IF(E39="","",IF(D39-E39>0,D39-E39,"")) | H39: EA | I39: 1.46 | J39: =E39*I39 -> 0
B40: Bières | C40: Cidre 33cl "La Genevoise du Terroir" | G40: =IF(E40="","",IF(D40-E40>0,D40-E40,"")) | H40: EA | I40: 3.45 | J40: =E40*I40 -> 0
A41: Catégorie : Consignes | G41: =IF(E41="","",IF(D41-E41>0,D41-E41,"")) | I41: TOTAL : | J41: =SUM(J42:J49) -> 3055
B42: Consignes | C42: Bouteille / Aligal consignée | E42: =E24 -> 1 | G42: =IF(E42="","",IF(D42-E42>0,D42-E42,"")) | H42: EA | I42: 100 | J42: =E42*I42 -> 100
...

Sheet Est Mobile 3
B1: TOTAL PRODUIT CONSOLIDE
B4: Catégories | C4: Valeur d'inventaire
B5: Bières | C5: =J23 -> 2977.85
B6: Consignes | C6: =J4 -> 0
B7: Vins | C7: =J50 -> 0
B8: Boissons avec alcool / Spiritueux | C8: =J78 -> 0
B9: Boissons sans alcool | C9: =J122 -> 129.01
B10: Caféterie | C10: =J176 -> 0
B11: Negoce | C11: =J187 -> 0
B12: Boulangerie | C12: =J193 -> 0
B13: Sauce & Condiments | C13: =J195 -> 0
B14: Surgelés | C14: =J208 -> 0
B15: Viandes | C15: =J214 -> 0
B16: Graisse & Huile | C16: =J222 -> 0
B17: Mono-usages | C17: =J224 -> 0
B18: Produit de nettoyage | C18: =J245 -> 22.45
B19: Divers | C19: =J257 -> 0
B20: TOTAL | C20: =C5+C6+C7+C8+C9+C10+C11+C12+C13+C14+C15+C16+C17+C18+C19 -> 3129.31
A21: INVENTAIRES STADE
B22: Catégorie | C22: Article d'inventaire | D22: MIN. REQUIS | E22: STOCKS FIN DE SERVICE | F22: QUANTITE A REMETTRE | G22: MANQUE / RUPTURE | H22: UNITE | I22: PRIX | J22: VALEUR
A23: Catégorie :Bières | E23: A REMPLIR ↓ | I23: TOTAL : | J23: =SUM(J24:J40) -> 2977.85
B24: Bières | C24: Aligal 2 7kg | D24: 2 | E24: 3 | G24: =IF(E24="","",IF(D24-E24>0,D24-E24,"")) | H24: EA | I24: 55.95 | J24: =E24*I24 -> 167.85
B25: Bières | C25: Brooklyn EIPA 30lt Fût | G25: =IF(E25="","",IF(D25-E25>0,D25-E25,"")) | H25: EA | I25: 173.1 | J25: =E25*I25 -> 0
B26: Bières | C26: Cardinal Blonde 20lt Fût | D26: 15 | E26: 17 | G26: =IF(E26="","",IF(D26-E26>0,D26-E26,"")) | H26: EA | I26: 75.4 | J26: =E26*I26 -> 1281.8
B27: Bières | C27: Servettienne 20lt Fût | D27: 15 | E27: 18 | G27: =IF(E27="","",IF(D27-E27>0,D27-E27,"")) | H27: EA | I27: 84.9 | J27: =E27*I27 -> 1528.2
B28: Bières | C28: Bonde la piece bouteille | G28: =IF(E28="","",IF(D28-E28>0,D28-E28,"")) | H28: EA | I28: 2.96 | J28: =E28*I28 -> 0
B29: Bières | C29: Blanche la piece bouteille | G29: =IF(E29="","",IF(D29-E29>0,D29-E29,"")) | H29: EA | I29: 2.96 | J29: =E29*I29 -> 0
B30: Bières | C30: IPA la piece bouteille | G30: =IF(E30="","",IF(D30-E30>0,D30-E30,"")) | H30: EA | I30: 2.96 | J30: =E30*I30 -> 0
B31: Bières | C31: Grimbergen blanche 20lt Fût | G31: =IF(E31="","",IF(D31-E31>0,D31-E31,"")) | H31: EA | I31: 107.2 | J31: =E31*I31 -> 0
B32: Bières | C32: Magners 30lt Fût | G32: =IF(E32="","",IF(D32-E32>0,D32-E32,"")) | H32: EA | I32: 170.7 | J32: =E32*I32 -> 0
B33: Bières | C33: Cardinal Blonde Citernes lt | G33: =IF(E33="","",IF(D33-E33>0,D33-E33,"")) | H33: lt | I33: 3.77 | J33: =E33*I33 -> 0
B34: Bières | C34: Valaisanne Bière de Cave - Bière bouteille | G34: =IF(E34="","",IF(D34-E34>0,D34-E34,"")) | H34: EA | I34: 2.56 | J34: =E34*I34 -> 0
B35: Bières | C35: Valaisanne IPA - Bière bouteille | G35: =IF(E35="","",IF(D35-E35>0,D35-E35,"")) | H35: EA | I35: 3.08 | J35: =E35*I35 -> 0
B36: Bières | C36: Valaisanne Pale Ale - Bière bouteille | G36: =IF(E36="","",IF(D36-E36>0,D36-E36,"")) | H36: EA | I36: 2.56 | J36: =E36*I36 -> 0
B37: Bières | C37: Cardinal - Bière bouteille | G37: =IF(E37="","",IF(D37-E37>0,D37-E37,"")) | H37: EA | I37: 1.41 | J37: =E37*I37 -> 0
B38: Bières | C38: San Miguel - Bière bouteille | G38: =IF(E38="","",IF(D38-E38>0,D38-E38,"")) | H38: EA | I38: 1.73 | J38: =E38*I38 -> 0
B39: Bières | C39: Cardinal sans alcool - Bière bouteille | G39: =IF(E39="","",IF(D39-E39>0,D39-E39,"")) | H39: EA | I39: 1.46 | J39: =E39*I39 -> 0
B40: Bières | C40: Cidre 33cl "La Genevoise du Terroir" | G40: =IF(E40="","",IF(D40-E40>0,D40-E40,"")) | H40: EA | I40: 3.45 | J40: =E40*I40 -> 0
A41: Catégorie : Consignes | G41: =IF(E41="","",IF(D41-E41>0,D41-E41,"")) | I41: TOTAL : | J41: =SUM(J42:J49) -> 2060
B42: Consignes | C42: Bouteille / Aligal consignée | E42: =E24 -> 3 | G42: =IF(E42="","",IF(D42-E42>0,D42-E42,"")) | H42: EA | I42: 100 | J42: =E42*I42 -> 300
...

Sheet Est 2
B1: TOTAL PRODUIT CONSOLIDE
B4: Catégories | C4: Valeur d'inventaire
B5: Bières | C5: =J23 -> 2779.7
B6: Consignes | C6: =J4 -> 0
B7: Vins | C7: =J50 -> 410.35
B8: Boissons avec alcool / Spiritueux | C8: =J78 -> 0
B9: Boissons sans alcool | C9: =J122 -> 2914.06
B10: Caféterie | C10: =J176 -> 0
B11: Negoce | C11: =J187 -> 0
B12: Boulangerie | C12: =J193 -> 0
B13: Sauce & Condiments | C13: =J195 -> 377.69
B14: Surgelés | C14: =J208 -> 2004.4
B15: Viandes | C15: =J214 -> 0
B16: Graisse & Huile | C16: =J222 -> 0
B17: Mono-usages | C17: =J224 -> 285.93
B18: Produit de nettoyage | C18: =J245 -> 294.92
B19: Divers | C19: =J257 -> 0
B20: TOTAL | C20: =C5+C6+C7+C8+C9+C10+C11+C12+C13+C14+C15+C16+C17+C18+C19 -> 9067.05
A21: INVENTAIRES STADE
B22: Catégorie | C22: Article d'inventaire | D22: MIN. REQUIS | E22: STOCKS FIN DE SERVICE | F22: QUANTITE A REMETTRE | G22: MANQUE / RUPTURE | H22: UNITE | I22: PRIX | J22: VALEUR
A23: Catégorie :Bières | E23: A REMPLIR ↓ | I23: TOTAL : | J23: =SUM(J24:J40) -> 2779.7
B24: Bières | C24: Aligal 2 7kg | D24: 2 | E24: 4 | G24: =IF(E24="","",IF(D24-E24>0,D24-E24,"")) | H24: EA | I24: 55.95 | J24: =E24*I24 -> 223.8
B25: Bières | C25: Brooklyn EIPA 30lt Fût | G25: =IF(E25="","",IF(D25-E25>0,D25-E25,"")) | H25: EA | I25: 173.1 | J25: =E25*I25 -> 0
B26: Bières | C26: Cardinal Blonde 20lt Fût | D26: 20 | E26: 8 | G26: =IF(E26="","",IF(D26-E26>0,D26-E26,"")) -> 12 | H26: EA | I26: 75.4 | J26: =E26*I26 -> 603.2
B27: Bières | C27: Servettienne 20lt Fût | D27: 20 | E27: 23 | G27: =IF(E27="","",IF(D27-E27>0,D27-E27,"")) | H27: EA | I27: 84.9 | J27: =E27*I27 -> 1952.7
B28: Bières | C28: Bonde la piece bouteille | G28: =IF(E28="","",IF(D28-E28>0,D28-E28,"")) | H28: EA | I28: 2.96 | J28: =E28*I28 -> 0
B29: Bières | C29: Blanche la piece bouteille | G29: =IF(E29="","",IF(D29-E29>0,D29-E29,"")) | H29: EA | I29: 2.96 | J29: =E29*I29 -> 0
B30: Bières | C30: IPA la piece bouteille | G30: =IF(E30="","",IF(D30-E30>0,D30-E30,"")) | H30: EA | I30: 2.96 | J30: =E30*I30 -> 0
B31: Bières | C31: Grimbergen blanche 20lt Fût | G31: =IF(E31="","",IF(D31-E31>0,D31-E31,"")) | H31: EA | I31: 107.2 | J31: =E31*I31 -> 0
B32: Bières | C32: Magners 30lt Fût | G32: =IF(E32="","",IF(D32-E32>0,D32-E32,"")) | H32: EA | I32: 170.7 | J32: =E32*I32 -> 0
B33: Bières | C33: Cardinal Blonde Citernes lt | G33: =IF(E33="","",IF(D33-E33>0,D33-E33,"")) | H33: lt | I33: 3.77 | J33: =E33*I33 -> 0
B34: Bières | C34: Valaisanne Bière de Cave - Bière bouteille | G34: =IF(E34="","",IF(D34-E34>0,D34-E34,"")) | H34: EA | I34: 2.56 | J34: =E34*I34 -> 0
B35: Bières | C35: Valaisanne IPA - Bière bouteille | G35: =IF(E35="","",IF(D35-E35>0,D35-E35,"")) | H35: EA | I35: 3.08 | J35: =E35*I35 -> 0
B36: Bières | C36: Valaisanne Pale Ale - Bière bouteille | G36: =IF(E36="","",IF(D36-E36>0,D36-E36,"")) | H36: EA | I36: 2.56 | J36: =E36*I36 -> 0
B37: Bières | C37: Cardinal - Bière bouteille | G37: =IF(E37="","",IF(D37-E37>0,D37-E37,"")) | H37: EA | I37: 1.41 | J37: =E37*I37 -> 0
B38: Bières | C38: San Miguel - Bière bouteille | G38: =IF(E38="","",IF(D38-E38>0,D38-E38,"")) | H38: EA | I38: 1.73 | J38: =E38*I38 -> 0
B39: Bières | C39: Cardinal sans alcool - Bière bouteille | G39: =IF(E39="","",IF(D39-E39>0,D39-E39,"")) | H39: EA | I39: 1.46 | J39: =E39*I39 -> 0
