Workbook
Name Début: 'COMMANDE GD-PUBLIC SFC'!#REF!
Name Début: 'COMMANDE GD-PUBLIC SFC'!#REF!
Name Début: 'COMMANDE GD-PUBLIC GSHC'!#REF!
Name Fin: 'COMMANDE GD-PUBLIC SFC'!#REF!
Name Fin: 'COMMANDE GD-PUBLIC SFC'!#REF!
Name Fin: 'COMMANDE GD-PUBLIC GSHC'!#REF!
Name HeureDécimR: '[1]Commande extra vierge'!$T$4:$T$154
Name HeureEstim2: 'COMMANDE GD-PUBLIC SFC'!$O$6:$O$159
Name HeureEstim2: 'COMMANDE GD-PUBLIC SFC'!$O$6:$O$159
Name HeureEstim2: 'COMMANDE GD-PUBLIC GSHC'!$O$6:$O$71
Name matin: 'COMMANDE GD-PUBLIC SFC'!#REF!
Name matin: 'COMMANDE GD-PUBLIC SFC'!#REF!
Name matin: 'COMMANDE GD-PUBLIC GSHC'!#REF!
Name nuit: 'COMMANDE GD-PUBLIC SFC'!#REF!
Name nuit: 'COMMANDE GD-PUBLIC SFC'!#REF!
Name nuit: 'COMMANDE GD-PUBLIC GSHC'!#REF!
Name Pause: 'COMMANDE GD-PUBLIC SFC'!#REF!
Name Pause: 'COMMANDE GD-PUBLIC SFC'!#REF!
Name Pause: 'COMMANDE GD-PUBLIC GSHC'!#REF!
Name S: '[2]COMMANDE GD-PUBLIC'!#REF!
Name S: '[2]COMMANDE GD-PUBLIC'!#REF!
Name S: '[3]COMMANDE GD-PUBLIC'!#REF!
Name Tarifs: 'COMMANDE GD-PUBLIC SFC'!$Q$6:$Q$159
Name Tarifs: 'COMMANDE GD-PUBLIC SFC'!$Q$6:$Q$159
Name Tarifs: 'COMMANDE GD-PUBLIC GSHC'!$Q$6:$Q$71
Name Tarifs2: '[1]Commande extra vierge'!$U$4:$U$154
Name Total: 'COMMANDE GD-PUBLIC SFC'!#REF!
Name Total: 'COMMANDE GD-PUBLIC SFC'!#REF!
Name Total: 'COMMANDE GD-PUBLIC GSHC'!#REF!
Name TotalCHF: 'COMMANDE GD-PUBLIC SFC'!#REF!
Name TotalCHF: 'COMMANDE GD-PUBLIC SFC'!#REF!
Name TotalCHF: 'COMMANDE GD-PUBLIC GSHC'!#REF!
Name TotalRéelCHF: '[1]Commande extra vierge'!$V$4:$V$154

Sheet COMMANDE GD-PUBLIC GSHC
I1: OUVERT | J1: MATCH
A2: MATCH GSHC X | C2: SCL TIGERS | D2: 45974 | I2: 0.76041667 | J2: 0.82291667 | S2: COLONNE MASQUÉE
A3: PARTIE PRIME | D3: PARTIE HOTELIS | I3: HORAIRES INFOS | U3: A | V3: B | W3: E | X3: F | Y3: G
A4: LIEU | B4: NBR | C4: POSTE | D4: NOM ET PRÉNOM | E4: N° CONTRAT | F4: EMAIL CANDIDATS | G4: N° TÉL | H4: SALAIRE HORAIRE | I4: DÉBUT | J4: FIN ESTIMÉE | K4: COLONNE MASQUÉE | L4: PAUSE | M4: TOTAL COLONNE MASQUÉE | N4: COLONNE MASQUÉE Nbr heure avant 6h après 23h | O4: TOTAL DÉCIMAL | P4: TOTAL HEURE NORMAL DÉCIMAL | Q4: TOTAL HEURE SUPPL. DÉCIMAL | S4: 0.25 | T4: 0.95833333 | U4: -0.95833333 | V4: -0.70833333 | W4: 0.00069444444 | X4: 0.040972222 | Y4: 8600
A5: BEV 1 | I5: 0.72916667 | J5: 0.9375 | K5: =J5+$Y$4 -> 8600.9375 | L5: 0 | M5: =IF($I5="","",IF($J5<$I5,($J5+86400)-$I5-$L5,$J5-$I5-$L5)) -> 0.20833333 | N5: =IF(J5="","",IF(AND($U$4<=(J5-$T$4),(J5-$T$4)<=$V$4),(K5-$T$4),"00:00")+IF(AND($W$4<=(J5-$T$4),(J5-$T$4)<=$X$4),(J5-$T$4),"00:00")+IF(($S$4-I5)<0,"00:00",($S$4-I5))) -> 0 | O5: =IF($C5="","",(HOUR($M5)*60+MINUTE($M5))/60) | P5: =IF(O5="","",O5-Q5) | Q5: =IF($C5="","",(HOUR($N5)*60+MINUTE($N5))/60)
I6: 0.75 | J6: 0.89583333 | K6: =J6+$Y$4 -> 8600.8958 | L6: 0 | M6: =IF($I6="","",IF($J6<$I6,($J6+86400)-$I6-$L6,$J6-$I6-$L6)) -> 0.14583333 | N6: =IF(J6="","",IF(AND($U$4<=(J6-$T$4),(J6-$T$4)<=$V$4),(K6-$T$4),"00:00")+IF(AND($W$4<=(J6-$T$4),(J6-$T$4)<=$X$4),(J6-$T$4),"00:00")+IF(($S$4-I6)<0,"00:00",($S$4-I6))) -> 0 | O6: =IF($C6="","",(HOUR($M6)*60+MINUTE($M6))/60) | P6: =IF(O6="","",O6-Q6) | Q6: =IF($C6="","",(HOUR($N6)*60+MINUTE($N6))/60)
I7: 0.77083333 | J7: 0.89583333 | K7: =J7+$Y$4 -> 8600.8958 | L7: 0 | M7: =IF($I7="","",IF($J7<$I7,($J7+86400)-$I7-$L7,$J7-$I7-$L7)) -> 0.125 | N7: =IF(J7="","",IF(AND($U$4<=(J7-$T$4),(J7-$T$4)<=$V$4),(K7-$T$4),"00:00")+IF(AND($W$4<=(J7-$T$4),(J7-$T$4)<=$X$4),(J7-$T$4),"00:00")+IF(($S$4-I7)<0,"00:00",($S$4-I7))) -> 0 | O7: =IF($C7="","",(HOUR($M7)*60+MINUTE($M7))/60) | P7: =IF(O7="","",O7-Q7) | Q7: =IF($C7="","",(HOUR($N7)*60+MINUTE($N7))/60)
I8: 0.79166667 | J8: 0.9375 | K8: =J8+$Y$4 -> 8600.9375 | L8: 0 | M8: =IF($I8="","",IF($J8<$I8,($J8+86400)-$I8-$L8,$J8-$I8-$L8)) -> 0.14583333 | N8: =IF(J8="","",IF(AND($U$4<=(J8-$T$4),(J8-$T$4)<=$V$4),(K8-$T$4),"00:00")+IF(AND($W$4<=(J8-$T$4),(J8-$T$4)<=$X$4),(J8-$T$4),"00:00")+IF(($S$4-I8)<0,"00:00",($S$4-I8))) -> 0 | O8: =IF($C8="","",(HOUR($M8)*60+MINUTE($M8))/60) | P8: =IF(O8="","",O8-Q8) | Q8: =IF($C8="","",(HOUR($N8)*60+MINUTE($N8))/60)
K9: =J9+$Y$4 -> 8600 | L9: 0 | M9: =IF($I9="","",IF($J9<$I9,($J9+86400)-$I9-$L9,$J9-$I9-$L9)) | N9: =IF(J9="","",IF(AND($U$4<=(J9-$T$4),(J9-$T$4)<=$V$4),(K9-$T$4),"00:00")+IF(AND($W$4<=(J9-$T$4),(J9-$T$4)<=$X$4),(J9-$T$4),"00:00")+IF(($S$4-I9)<0,"00:00",($S$4-I9))) | O9: =IF($C9="","",(HOUR($M9)*60+MINUTE($M9))/60) | P9: =IF(O9="","",O9-Q9) | Q9: =IF($C9="","",(HOUR($N9)*60+MINUTE($N9))/60)
K10: =J10+$Y$4 -> 8600 | L10: 0 | M10: =IF($I10="","",IF($J10<$I10,($J10+86400)-$I10-$L10,$J10-$I10-$L10)) | N10: =IF(J10="","",IF(AND($U$4<=(J10-$T$4),(J10-$T$4)<=$V$4),(K10-$T$4),"00:00")+IF(AND($W$4<=(J10-$T$4),(J10-$T$4)<=$X$4),(J10-$T$4),"00:00")+IF(($S$4-I10)<0,"00:00",($S$4-I10))) | O10: =IF($C10="","",(HOUR($M10)*60+MINUTE($M10))/60) | P10: =IF(O10="","",O10-Q10) | Q10: =IF($C10="","",(HOUR($N10)*60+MINUTE($N10))/60)
A11: BEV 2 | I11: 0.72916667 | J11: 0.9375 | K11: =J11+$Y$4 -> 8600.9375 | L11: 0 | M11: =IF($I11="","",IF($J11<$I11,($J11+86400)-$I11-$L11,$J11-$I11-$L11)) -> 0.20833333 | N11: =IF(J11="","",IF(AND($U$4<=(J11-$T$4),(J11-$T$4)<=$V$4),(K11-$T$4),"00:00")+IF(AND($W$4<=(J11-$T$4),(J11-$T$4)<=$X$4),(J11-$T$4),"00:00")+IF(($S$4-I11)<0,"00:00",($S$4-I11))) -> 0 | O11: =IF($C11="","",(HOUR($M11)*60+MINUTE($M11))/60) | P11: =IF(O11="","",O11-Q11) | Q11: =IF($C11="","",(HOUR($N11)*60+MINUTE($N11))/60)
I12: 0.75 | J12: 0.89583333 | K12: =J12+$Y$4 -> 8600.8958 | L12: 0 | M12: =IF($I12="","",IF($J12<$I12,($J12+86400)-$I12-$L12,$J12-$I12-$L12)) -> 0.14583333 | N12: =IF(J12="","",IF(AND($U$4<=(J12-$T$4),(J12-$T$4)<=$V$4),(K12-$T$4),"00:00")+IF(AND($W$4<=(J12-$T$4),(J12-$T$4)<=$X$4),(J12-$T$4),"00:00")+IF(($S$4-I12)<0,"00:00",($S$4-I12))) -> 0 | O12: =IF($C12="","",(HOUR($M12)*60+MINUTE($M12))/60) | P12: =IF(O12="","",O12-Q12) | Q12: =IF($C12="","",(HOUR($N12)*60+MINUTE($N12))/60)
I13: 0.77083333 | J13: 0.89583333 | K13: =J13+$Y$4 -> 8600.8958 | L13: 0 | M13: =IF($I13="","",IF($J13<$I13,($J13+86400)-$I13-$L13,$J13-$I13-$L13)) -> 0.125 | N13: =IF(J13="","",IF(AND($U$4<=(J13-$T$4),(J13-$T$4)<=$V$4),(K13-$T$4),"00:00")+IF(AND($W$4<=(J13-$T$4),(J13-$T$4)<=$X$4),(J13-$T$4),"00:00")+IF(($S$4-I13)<0,"00:00",($S$4-I13))) -> 0 | O13: =IF($C13="","",(HOUR($M13)*60+MINUTE($M13))/60) | P13: =IF(O13="","",O13-Q13) | Q13: =IF($C13="","",(HOUR($N13)*60+MINUTE($N13))/60)
I14: 0.79166667 | J14: 0.9375 | K14: =J14+$Y$4 -> 8600.9375 | L14: 0 | M14: =IF($I14="","",IF($J14<$I14,($J14+86400)-$I14-$L14,$J14-$I14-$L14)) -> 0.14583333 | N14: =IF(J14="","",IF(AND($U$4<=(J14-$T$4),(J14-$T$4)<=$V$4),(K14-$T$4),"00:00")+IF(AND($W$4<=(J14-$T$4),(J14-$T$4)<=$X$4),(J14-$T$4),"00:00")+IF(($S$4-I14)<0,"00:00",($S$4-I14))) -> 0 | O14: =IF($C14="","",(HOUR($M14)*60+MINUTE($M14))/60) | P14: =IF(O14="","",O14-Q14) | Q14: =IF($C14="","",(HOUR($N14)*60+MINUTE($N14))/60)
K15: =J15+$Y$4 -> 8600 | L15: 0 | M15: =IF($I15="","",IF($J15<$I15,($J15+86400)-$I15-$L15,$J15-$I15-$L15)) | N15: =IF(J15="","",IF(AND($U$4<=(J15-$T$4),(J15-$T$4)<=$V$4),(K15-$T$4),"00:00")+IF(AND($W$4<=(J15-$T$4),(J15-$T$4)<=$X$4),(J15-$T$4),"00:00")+IF(($S$4-I15)<0,"00:00",($S$4-I15))) | O15: =IF($C15="","",(HOUR($M15)*60+MINUTE($M15))/60) | P15: =IF(O15="","",O15-Q15) | Q15: =IF($C15="","",(HOUR($N15)*60+MINUTE($N15))/60)
K16: =J16+$Y$4 -> 8600 | L16: 0 | M16: =IF($I16="","",IF($J16<$I16,($J16+86400)-$I16-$L16,$J16-$I16-$L16)) | N16: =IF(J16="","",IF(AND($U$4<=(J16-$T$4),(J16-$T$4)<=$V$4),(K16-$T$4),"00:00")+IF(AND($W$4<=(J16-$T$4),(J16-$T$4)<=$X$4),(J16-$T$4),"00:00")+IF(($S$4-I16)<0,"00:00",($S$4-I16))) | O16: =IF($C16="","",(HOUR($M16)*60+MINUTE($M16))/60) | P16: =IF(O16="","",O16-Q16) | Q16: =IF($C16="","",(HOUR($N16)*60+MINUTE($N16))/60)
A17: BEV 3 | I17: 0.72916667 | J17: 0.9375 | K17: =J17+$Y$4 -> 8600.9375 | L17: 0 | M17: =IF($I17="","",IF($J17<$I17,($J17+86400)-$I17-$L17,$J17-$I17-$L17)) -> 0.20833333 | N17: =IF(J17="","",IF(AND($U$4<=(J17-$T$4),(J17-$T$4)<=$V$4),(K17-$T$4),"00:00")+IF(AND($W$4<=(J17-$T$4),(J17-$T$4)<=$X$4),(J17-$T$4),"00:00")+IF(($S$4-I17)<0,"00:00",($S$4-I17))) -> 0 | O17: =IF($C17="","",(HOUR($M17)*60+MINUTE($M17))/60) | P17: =IF(O17="","",O17-Q17) | Q17: =IF($C17="","",(HOUR($N17)*60+MINUTE($N17))/60)
I18: 0.75 | J18: 0.89583333 | K18: =J18+$Y$4 -> 8600.8958 | L18: 0 | M18: =IF($I18="","",IF($J18<$I18,($J18+86400)-$I18-$L18,$J18-$I18-$L18)) -> 0.14583333 | N18: =IF(J18="","",IF(AND($U$4<=(J18-$T$4),(J18-$T$4)<=$V$4),(K18-$T$4),"00:00")+IF(AND($W$4<=(J18-$T$4),(J18-$T$4)<=$X$4),(J18-$T$4),"00:00")+IF(($S$4-I18)<0,"00:00",($S$4-I18))) -> 0 | O18: =IF($C18="","",(HOUR($M18)*60+MINUTE($M18))/60) | P18: =IF(O18="","",O18-Q18) | Q18: =IF($C18="","",(HOUR($N18)*60+MINUTE($N18))/60)
I19: 0.77083333 | J19: 0.89583333 | K19: =J19+$Y$4 -> 8600.8958 | L19: 0 | M19: =IF($I19="","",IF($J19<$I19,($J19+86400)-$I19-$L19,$J19-$I19-$L19)) -> 0.125 | N19: =IF(J19="","",IF(AND($U$4<=(J19-$T$4),(J19-$T$4)<=$V$4),(K19-$T$4),"00:00")+IF(AND($W$4<=(J19-$T$4),(J19-$T$4)<=$X$4),(J19-$T$4),"00:00")+IF(($S$4-I19)<0,"00:00",($S$4-I19))) -> 0 | O19: =IF($C19="","",(HOUR($M19)*60+MINUTE($M19))/60) | P19: =IF(O19="","",O19-Q19) | Q19: =IF($C19="","",(HOUR($N19)*60+MINUTE($N19))/60)
I20: 0.79166667 | J20: 0.9375 | K20: =J20+$Y$4 -> 8600.9375 | L20: 0 | M20: =IF($I20="","",IF($J20<$I20,($J20+86400)-$I20-$L20,$J20-$I20-$L20)) -> 0.14583333 | N20: =IF(J20="","",IF(AND($U$4<=(J20-$T$4),(J20-$T$4)<=$V$4),(K20-$T$4),"00:00")+IF(AND($W$4<=(J20-$T$4),(J20-$T$4)<=$X$4),(J20-$T$4),"00:00")+IF(($S$4-I20)<0,"00:00",($S$4-I20))) -> 0 | O20: =IF($C20="","",(HOUR($M20)*60+MINUTE($M20))/60) | P20: =IF(O20="","",O20-Q20) | Q20: =IF($C20="","",(HOUR($N20)*60+MINUTE($N20))/60)
K21: =J21+$Y$4 -> 8600 | L21: 0 | M21: =IF($I21="","",IF($J21<$I21,($J21+86400)-$I21-$L21,$J21-$I21-$L21)) | N21: =IF(J21="","",IF(AND($U$4<=(J21-$T$4),(J21-$T$4)<=$V$4),(K21-$T$4),"00:00")+IF(AND($W$4<=(J21-$T$4),(J21-$T$4)<=$X$4),(J21-$T$4),"00:00")+IF(($S$4-I21)<0,"00:00",($S$4-I21))) | O21: =IF($C21="","",(HOUR($M21)*60+MINUTE($M21))/60) | P21: =IF(O21="","",O21-Q21) | Q21: =IF($C21="","",(HOUR($N21)*60+MINUTE($N21))/60)
K22: =J22+$Y$4 -> 8600 | L22: 0 | M22: =IF($I22="","",IF($J22<$I22,($J22+86400)-$I22-$L22,$J22-$I22-$L22)) | N22: =IF(J22="","",IF(AND($U$4<=(J22-$T$4),(J22-$T$4)<=$V$4),(K22-$T$4),"00:00")+IF(AND($W$4<=(J22-$T$4),(J22-$T$4)<=$X$4),(J22-$T$4),"00:00")+IF(($S$4-I22)<0,"00:00",($S$4-I22))) | O22: =IF($C22="","",(HOUR($M22)*60+MINUTE($M22))/60) | P22: =IF(O22="","",O22-Q22) | Q22: =IF($C22="","",(HOUR($N22)*60+MINUTE($N22))/60)
A23: FOOD 1 | I23: 0.75 | J23: 0.9375 | K23: =J23+$Y$4 -> 8600.9375 | L23: 0 | M23: =IF($I23="","",IF($J23<$I23,($J23+86400)-$I23-$L23,$J23-$I23-$L23)) -> 0.1875 | N23: =IF(J23="","",IF(AND($U$4<=(J23-$T$4),(J23-$T$4)<=$V$4),(K23-$T$4),"00:00")+IF(AND($W$4<=(J23-$T$4),(J23-$T$4)<=$X$4),(J23-$T$4),"00:00")+IF(($S$4-I23)<0,"00:00",($S$4-I23))) -> 0 | O23: =IF($C23="","",(HOUR($M23)*60+MINUTE($M23))/60) | P23: =IF(O23="","",O23-Q23) | Q23: =IF($C23="","",(HOUR($N23)*60+MINUTE($N23))/60)
I24: 0.72916667 | J24: 0.91666667 | K24: =J24+$Y$4 -> 8600.9167 | L24: 0 | M24: =IF($I24="","",IF($J24<$I24,($J24+86400)-$I24-$L24,$J24-$I24-$L24)) -> 0.1875 | N24: =IF(J24="","",IF(AND($U$4<=(J24-$T$4),(J24-$T$4)<=$V$4),(K24-$T$4),"00:00")+IF(AND($W$4<=(J24-$T$4),(J24-$T$4)<=$X$4),(J24-$T$4),"00:00")+IF(($S$4-I24)<0,"00:00",($S$4-I24))) -> 0 | O24: =IF($C24="","",(HOUR($M24)*60+MINUTE($M24))/60) | P24: =IF(O24="","",O24-Q24) | Q24: =IF($C24="","",(HOUR($N24)*60+MINUTE($N24))/60)
K25: =J25+$Y$4 -> 8600 | L25: 0 | M25: =IF($I25="","",IF($J25<$I25,($J25+86400)-$I25-$L25,$J25-$I25-$L25)) | N25: =IF(J25="","",IF(AND($U$4<=(J25-$T$4),(J25-$T$4)<=$V$4),(K25-$T$4),"00:00")+IF(AND($W$4<=(J25-$T$4),(J25-$T$4)<=$X$4),(J25-$T$4),"00:00")+IF(($S$4-I25)<0,"00:00",($S$4-I25))) | O25: =IF($C25="","",(HOUR($M25)*60+MINUTE($M25))/60) | P25: =IF(O25="","",O25-Q25) | Q25: =IF($C25="","",(HOUR($N25)*60+MINUTE($N25))/60)
K26: =J26+$Y$4 -> 8600 | L26: 0 | M26: =IF($I26="","",IF($J26<$I26,($J26+86400)-$I26-$L26,$J26-$I26-$L26)) | N26: =IF(J26="","",IF(AND($U$4<=(J26-$T$4),(J26-$T$4)<=$V$4),(K26-$T$4),"00:00")+IF(AND($W$4<=(J26-$T$4),(J26-$T$4)<=$X$4),(J26-$T$4),"00:00")+IF(($S$4-I26)<0,"00:00",($S$4-I26))) | O26: =IF($C26="","",(HOUR($M26)*60+MINUTE($M26))/60) | P26: =IF(O26="","",O26-Q26) | Q26: =IF($C26="","",(HOUR($N26)*60+MINUTE($N26))/60)
A27: FOOD 2 | I27: 0.75 | J27: 0.9375 | K27: =J27+$Y$4 -> 8600.9375 | L27: 0 | M27: =IF($I27="","",IF($J27<$I27,($J27+86400)-$I27-$L27,$J27-$I27-$L27)) -> 0.1875 | N27: =IF(J27="","",IF(AND($U$4<=(J27-$T$4),(J27-$T$4)<=$V$4),(K27-$T$4),"00:00")+IF(AND($W$4<=(J27-$T$4),(J27-$T$4)<=$X$4),(J27-$T$4),"00:00")+IF(($S$4-I27)<0,"00:00",($S$4-I27))) -> 0 | O27: =IF($C27="","",(HOUR($M27)*60+MINUTE($M27))/60) | P27: =IF(O27="","",O27-Q27) | Q27: =IF($C27="","",(HOUR($N27)*60+MINUTE($N27))/60)
I28: 0.79166667 | J28: 0.9375 | K28: =J28+$Y$4 -> 8600.9375 | L28: 0 | M28: =IF($I28="","",IF($J28<$I28,($J28+86400)-$I28-$L28,$J28-$I28-$L28)) -> 0.14583333 | N28: =IF(J28="","",IF(AND($U$4<=(J28-$T$4),(J28-$T$4)<=$V$4),(K28-$T$4),"00:00")+IF(AND($W$4<=(J28-$T$4),(J28-$T$4)<=$X$4),(J28-$T$4),"00:00")+IF(($S$4-I28)<0,"00:00",($S$4-I28))) -> 0 | O28: =IF($C28="","",(HOUR($M28)*60+MINUTE($M28))/60) | P28: =IF(O28="","",O28-Q28) | Q28: =IF($C28="","",(HOUR($N28)*60+MINUTE($N28))/60)
K29: =J29+$Y$4 -> 8600 | L29: 0 | M29: =IF($I29="","",IF($J29<$I29,($J29+86400)-$I29-$L29,$J29-$I29-$L29)) | N29: =IF(J29="","",IF(AND($U$4<=(J29-$T$4),(J29-$T$4)<=$V$4),(K29-$T$4),"00:00")+IF(AND($W$4<=(J29-$T$4),(J29-$T$4)<=$X$4),(J29-$T$4),"00:00")+IF(($S$4-I29)<0,"00:00",($S$4-I29))) | O29: =IF($C29="","",(HOUR($M29)*60+MINUTE($M29))/60) | P29: =IF(O29="","",O29-Q29) | Q29: =IF($C29="","",(HOUR($N29)*60+MINUTE($N29))/60)
K30: =J30+$Y$4 -> 8600 | L30: 0 | M30: =IF($I30="","",IF($J30<$I30,($J30+86400)-$I30-$L30,$J30-$I30-$L30)) | N30: =IF(J30="","",IF(AND($U$4<=(J30-$T$4),(J30-$T$4)<=$V$4),(K30-$T$4),"00:00")+IF(AND($W$4<=(J30-$T$4),(J30-$T$4)<=$X$4),(J30-$T$4),"00:00")+IF(($S$4-I30)<0,"00:00",($S$4-I30))) | O30: =IF($C30="","",(HOUR($M30)*60+MINUTE($M30))/60) | P30: =IF(O30="","",O30-Q30) | Q30: =IF($C30="","",(HOUR($N30)*60+MINUTE($N30))/60)
A31: CHALET 1 | I31: 0.72916667 | J31: 0.9375 | K31: =J31+$Y$4 -> 8600.9375 | L31: 0 | M31: =IF($I31="","",IF($J31<$I31,($J31+86400)-$I31-$L31,$J31-$I31-$L31)) -> 0.20833333 | N31: =IF(J31="","",IF(AND($U$4<=(J31-$T$4),(J31-$T$4)<=$V$4),(K31-$T$4),"00:00")+IF(AND($W$4<=(J31-$T$4),(J31-$T$4)<=$X$4),(J31-$T$4),"00:00")+IF(($S$4-I31)<0,"00:00",($S$4-I31))) -> 0 | O31: =IF($C31="","",(HOUR($M31)*60+MINUTE($M31))/60) | P31: =IF(O31="","",O31-Q31) | Q31: =IF($C31="","",(HOUR($N31)*60+MINUTE($N31))/60)
I32: 0.75 | J32: 0.89583333 | K32: =J32+$Y$4 -> 8600.8958 | L32: 0 | M32: =IF($I32="","",IF($J32<$I32,($J32+86400)-$I32-$L32,$J32-$I32-$L32)) -> 0.14583333 | N32: =IF(J32="","",IF(AND($U$4<=(J32-$T$4),(J32-$T$4)<=$V$4),(K32-$T$4),"00:00")+IF(AND($W$4<=(J32-$T$4),(J32-$T$4)<=$X$4),(J32-$T$4),"00:00")+IF(($S$4-I32)<0,"00:00",($S$4-I32))) -> 0 | O32: =IF($C32="","",(HOUR($M32)*60+MINUTE($M32))/60) | P32: =IF(O32="","",O32-Q32) | Q32: =IF($C32="","",(HOUR($N32)*60+MINUTE($N32))/60)
I33: 0.72916667 | J33: 0.91666667 | K33: =J33+$Y$4 -> 8600.9167 | L33: 0 | M33: =IF($I33="","",IF($J33<$I33,($J33+86400)-$I33-$L33,$J33-$I33-$L33)) -> 0.1875 | N33: =IF(J33="","",IF(AND($U$4<=(J33-$T$4),(J33-$T$4)<=$V$4),(K33-$T$4),"00:00")+IF(AND($W$4<=(J33-$T$4),(J33-$T$4)<=$X$4),(J33-$T$4),"00:00")+IF(($S$4-I33)<0,"00:00",($S$4-I33))) -> 0 | O33: =IF($C33="","",(HOUR($M33)*60+MINUTE($M33))/60) | P33: =IF(O33="","",O33-Q33) | Q33: =IF($C33="","",(HOUR($N33)*60+MINUTE($N33))/60)
K34: =J34+$Y$4 -> 8600 | L34: 0 | M34: =IF($I34="","",IF($J34<$I34,($J34+86400)-$I34-$L34,$J34-$I34-$L34)) | N34: =IF(J34="","",IF(AND($U$4<=(J34-$T$4),(J34-$T$4)<=$V$4),(K34-$T$4),"00:00")+IF(AND($W$4<=(J34-$T$4),(J34-$T$4)<=$X$4),(J34-$T$4),"00:00")+IF(($S$4-I34)<0,"00:00",($S$4-I34))) | O34: =IF($C34="","",(HOUR($M34)*60+MINUTE($M34))/60) | P34: =IF(O34="","",O34-Q34) | Q34: =IF($C34="","",(HOUR($N34)*60+MINUTE($N34))/60)
A35: CHALET 2 | I35: 0.72916667 | J35: 0.9375 | K35: =J35+$Y$4 -> 8600.9375 | L35: 0 | M35: =IF($I35="","",IF($J35<$I35,($J35+86400)-$I35-$L35,$J35-$I35-$L35)) -> 0.20833333 | N35: =IF(J35="","",IF(AND($U$4<=(J35-$T$4),(J35-$T$4)<=$V$4),(K35-$T$4),"00:00")+IF(AND($W$4<=(J35-$T$4),(J35-$T$4)<=$X$4),(J35-$T$4),"00:00")+IF(($S$4-I35)<0,"00:00",($S$4-I35))) -> 0 | O35: =IF($C35="","",(HOUR($M35)*60+MINUTE($M35))/60) | P35: =IF(O35="","",O35-Q35) | Q35: =IF($C35="","",(HOUR($N35)*60+MINUTE($N35))/60)
I36: 0.72916667 | J36: 0.91666667 | K36: =J36+$Y$4 -> 8600.9167 | L36: 0 | M36: =IF($I36="","",IF($J36<$I36,($J36+86400)-$I36-$L36,$J36-$I36-$L36)) -> 0.1875 | N36: =IF(J36="","",IF(AND($U$4<=(J36-$T$4),(J36-$T$4)<=$V$4),(K36-$T$4),"00:00")+IF(AND($W$4<=(J36-$T$4),(J36-$T$4)<=$X$4),(J36-$T$4),"00:00")+IF(($S$4-I36)<0,"00:00",($S$4-I36))) -> 0 | O36: =IF($C36="","",(HOUR($M36)*60+MINUTE($M36))/60) | P36: =IF(O36="","",O36-Q36) | Q36: =IF($C36="","",(HOUR($N36)*60+MINUTE($N36))/60)
K37: =J37+$Y$4 -> 8600 | L37: 0 | M37: =IF($I37="","",IF($J37<$I37,($J37+86400)-$I37-$L37,$J37-$I37-$L37)) | N37: =IF(J37="","",IF(AND($U$4<=(J37-$T$4),(J37-$T$4)<=$V$4),(K37-$T$4),"00:00")+IF(AND($W$4<=(J37-$T$4),(J37-$T$4)<=$X$4),(J37-$T$4),"00:00")+IF(($S$4-I37)<0,"00:00",($S$4-I37))) | O37: =IF($C37="","",(HOUR($M37)*60+MINUTE($M37))/60) | P37: =IF(O37="","",O37-Q37) | Q37: =IF($C37="","",(HOUR($N37)*60+MINUTE($N37))/60)
K38: =J38+$Y$4 -> 8600 | L38: 0 | M38: =IF($I38="","",IF($J38<$I38,($J38+86400)-$I38-$L38,$J38-$I38-$L38)) | N38: =IF(J38="","",IF(AND($U$4<=(J38-$T$4),(J38-$T$4)<=$V$4),(K38-$T$4),"00:00")+IF(AND($W$4<=(J38-$T$4),(J38-$T$4)<=$X$4),(J38-$T$4),"00:00")+IF(($S$4-I38)<0,"00:00",($S$4-I38))) | O38: =IF($C38="","",(HOUR($M38)*60+MINUTE($M38))/60) | P38: =IF(O38="","",O38-Q38) | Q38: =IF($C38="","",(HOUR($N38)*60+MINUTE($N38))/60)
A39: CHALET 3 | I39: 0.72916667 | J39: 0.9375 | K39: =J39+$Y$4 -> 8600.9375 | L39: 0 | M39: =IF($I39="","",IF($J39<$I39,($J39+86400)-$I39-$L39,$J39-$I39-$L39)) -> 0.20833333 | N39: =IF(J39="","",IF(AND($U$4<=(J39-$T$4),(J39-$T$4)<=$V$4),(K39-$T$4),"00:00")+IF(AND($W$4<=(J39-$T$4),(J39-$T$4)<=$X$4),(J39-$T$4),"00:00")+IF(($S$4-I39)<0,"00:00",($S$4-I39))) -> 0 | O39: =IF($C39="","",(HOUR($M39)*60+MINUTE($M39))/60) | P39: =IF(O39="","",O39-Q39) | Q39: =IF($C39="","",(HOUR($N39)*60+MINUTE($N39))/60)
I40: 0.75 | J40: 0.89583333 | K40: =J40+$Y$4 -> 8600.8958 | L40: 0 | M40: =IF($I40="","",IF($J40<$I40,($J40+86400)-$I40-$L40,$J40-$I40-$L40)) -> 0.14583333 | N40: =IF(J40="","",IF(AND($U$4<=(J40-$T$4),(J40-$T$4)<=$V$4),(K40-$T$4),"00:00")+IF(AND($W$4<=(J40-$T$4),(J40-$T$4)<=$X$4),(J40-$T$4),"00:00")+IF(($S$4-I40)<0,"00:00",($S$4-I40))) -> 0 | O40: =IF($C40="","",(HOUR($M40)*60+MINUTE($M40))/60) | P40: =IF(O40="","",O40-Q40) | Q40: =IF($C40="","",(HOUR($N40)*60+MINUTE($N40))/60)
...

Sheet FEUILLES HEURES
B2: ='COMMANDE GD-PUBLIC GSHC'!$A$2 -> MATCH GSHC X | C2: ='COMMANDE GD-PUBLIC GSHC'!$C$2 -> SCL TIGERS | E2: DATE | F2: ='COMMANDE GD-PUBLIC GSHC'!$D$2 -> 45974
B4: HEURE DÉBUT MATCH | C4: ='COMMANDE GD-PUBLIC GSHC'!$J$2 -> 0.82291667 | E4: LIEU | F4: PATINOIRE DES VERNETS
B7: POINT DE VENTE | C7: FONCTION | D7: HORAIRES DE PRÉSENCE | H7: SIGNATURE
B8: ='COMMANDE GD-PUBLIC GSHC'!A5 -> BEV 1 | D8: ARRIVÉE | E8: PAUSE | F8: DÉPART | G8: REMARQUE / APPRÉCIATION PAR LE RESPONSABLE
B9: =IF('COMMANDE GD-PUBLIC GSHC'!D5="","",'COMMANDE GD-PUBLIC GSHC'!D5) | C9: =IF('COMMANDE GD-PUBLIC GSHC'!C5="","",'COMMANDE GD-PUBLIC GSHC'!C5) | D9: =IF('COMMANDE GD-PUBLIC GSHC'!I5="","",'COMMANDE GD-PUBLIC GSHC'!I5) -> 0.72916667
B10: =IF('COMMANDE GD-PUBLIC GSHC'!D6="","",'COMMANDE GD-PUBLIC GSHC'!D6) | C10: =IF('COMMANDE GD-PUBLIC GSHC'!C6="","",'COMMANDE GD-PUBLIC GSHC'!C6) | D10: =IF('COMMANDE GD-PUBLIC GSHC'!I6="","",'COMMANDE GD-PUBLIC GSHC'!I6) -> 0.75
B11: =IF('COMMANDE GD-PUBLIC GSHC'!D7="","",'COMMANDE GD-PUBLIC GSHC'!D7) | C11: =IF('COMMANDE GD-PUBLIC GSHC'!C7="","",'COMMANDE GD-PUBLIC GSHC'!C7) | D11: =IF('COMMANDE GD-PUBLIC GSHC'!I7="","",'COMMANDE GD-PUBLIC GSHC'!I7) -> 0.77083333
B12: =IF('COMMANDE GD-PUBLIC GSHC'!D8="","",'COMMANDE GD-PUBLIC GSHC'!D8) | C12: =IF('COMMANDE GD-PUBLIC GSHC'!C8="","",'COMMANDE GD-PUBLIC GSHC'!C8) | D12: =IF('COMMANDE GD-PUBLIC GSHC'!I8="","",'COMMANDE GD-PUBLIC GSHC'!I8) -> 0.79166667
B13: =IF('COMMANDE GD-PUBLIC GSHC'!D9="","",'COMMANDE GD-PUBLIC GSHC'!D9) | C13: =IF('COMMANDE GD-PUBLIC GSHC'!C9="","",'COMMANDE GD-PUBLIC GSHC'!C9) | D13: =IF('COMMANDE GD-PUBLIC GSHC'!I9="","",'COMMANDE GD-PUBLIC GSHC'!I9)
B14: =IF('COMMANDE GD-PUBLIC GSHC'!D10="","",'COMMANDE GD-PUBLIC GSHC'!D10) | C14: =IF('COMMANDE GD-PUBLIC GSHC'!C10="","",'COMMANDE GD-PUBLIC GSHC'!C10) | D14: =IF('COMMANDE GD-PUBLIC GSHC'!I10="","",'COMMANDE GD-PUBLIC GSHC'!I10)
B19: ='COMMANDE GD-PUBLIC GSHC'!$A$2 -> MATCH GSHC X | C19: ='COMMANDE GD-PUBLIC GSHC'!$C$2 -> SCL TIGERS | E19: DATE | F19: ='COMMANDE GD-PUBLIC GSHC'!$D$2 -> 45974
B21: HEURE DÉBUT MATCH | C21: ='COMMANDE GD-PUBLIC GSHC'!$J$2 -> 0.82291667 | E21: LIEU | F21: PATINOIRE DES VERNETS
B24: POINT DE VENTE | C24: FONCTION | D24: HORAIRES DE PRÉSENCE | H24: SIGNATURE
B25: ='COMMANDE GD-PUBLIC GSHC'!A11 -> BEV 2 | D25: ARRIVÉE | E25: PAUSE | F25: DÉPART | G25: REMARQUE / APPRÉCIATION PAR LE RESPONSABLE
B26: =IF('COMMANDE GD-PUBLIC GSHC'!D11="","",'COMMANDE GD-PUBLIC GSHC'!D11) | C26: =IF('COMMANDE GD-PUBLIC GSHC'!C11="","",'COMMANDE GD-PUBLIC GSHC'!C11) | D26: =IF('COMMANDE GD-PUBLIC GSHC'!I11="","",'COMMANDE GD-PUBLIC GSHC'!I11) -> 0.72916667
B27: =IF('COMMANDE GD-PUBLIC GSHC'!D12="","",'COMMANDE GD-PUBLIC GSHC'!D12) | C27: =IF('COMMANDE GD-PUBLIC GSHC'!C12="","",'COMMANDE GD-PUBLIC GSHC'!C12) | D27: =IF('COMMANDE GD-PUBLIC GSHC'!I12="","",'COMMANDE GD-PUBLIC GSHC'!I12) -> 0.75
B28: =IF('COMMANDE GD-PUBLIC GSHC'!D13="","",'COMMANDE GD-PUBLIC GSHC'!D13) | C28: =IF('COMMANDE GD-PUBLIC GSHC'!C13="","",'COMMANDE GD-PUBLIC GSHC'!C13) | D28: =IF('COMMANDE GD-PUBLIC GSHC'!I13="","",'COMMANDE GD-PUBLIC GSHC'!I13) -> 0.77083333
B29: =IF('COMMANDE GD-PUBLIC GSHC'!D14="","",'COMMANDE GD-PUBLIC GSHC'!D14) | C29: =IF('COMMANDE GD-PUBLIC GSHC'!C14="","",'COMMANDE GD-PUBLIC GSHC'!C14) | D29: =IF('COMMANDE GD-PUBLIC GSHC'!I14="","",'COMMANDE GD-PUBLIC GSHC'!I14) -> 0.79166667
B30: =IF('COMMANDE GD-PUBLIC GSHC'!D15="","",'COMMANDE GD-PUBLIC GSHC'!D15) | C30: =IF('COMMANDE GD-PUBLIC GSHC'!C15="","",'COMMANDE GD-PUBLIC GSHC'!C15) | D30: =IF('COMMANDE GD-PUBLIC GSHC'!I15="","",'COMMANDE GD-PUBLIC GSHC'!I15)
B31: =IF('COMMANDE GD-PUBLIC GSHC'!D16="","",'COMMANDE GD-PUBLIC GSHC'!D16) | C31: =IF('COMMANDE GD-PUBLIC GSHC'!C16="","",'COMMANDE GD-PUBLIC GSHC'!C16) | D31: =IF('COMMANDE GD-PUBLIC GSHC'!I16="","",'COMMANDE GD-PUBLIC GSHC'!I16)
B36: ='COMMANDE GD-PUBLIC GSHC'!$A$2 -> MATCH GSHC X | C36: ='COMMANDE GD-PUBLIC GSHC'!$C$2 -> SCL TIGERS | E36: DATE | F36: ='COMMANDE GD-PUBLIC GSHC'!$D$2 -> 45974
B38: HEURE DÉBUT MATCH | C38: ='COMMANDE GD-PUBLIC GSHC'!$J$2 -> 0.82291667 | E38: LIEU | F38: PATINOIRE DES VERNETS
B41: POINT DE VENTE | C41: FONCTION | D41: HORAIRES DE PRÉSENCE | H41: SIGNATURE
B42: ='COMMANDE GD-PUBLIC GSHC'!A17 -> BEV 3 | D42: ARRIVÉE | E42: PAUSE | F42: DÉPART | G42: REMARQUE / APPRÉCIATION PAR LE RESPONSABLE
B43: =IF('COMMANDE GD-PUBLIC GSHC'!D17="","",'COMMANDE GD-PUBLIC GSHC'!D17) | C43: =IF('COMMANDE GD-PUBLIC GSHC'!C17="","",'COMMANDE GD-PUBLIC GSHC'!C17) | D43: =IF('COMMANDE GD-PUBLIC GSHC'!I17="","",'COMMANDE GD-PUBLIC GSHC'!I17) -> 0.72916667
B44: =IF('COMMANDE GD-PUBLIC GSHC'!D18="","",'COMMANDE GD-PUBLIC GSHC'!D18) | C44: =IF('COMMANDE GD-PUBLIC GSHC'!C18="","",'COMMANDE GD-PUBLIC GSHC'!C18) | D44: =IF('COMMANDE GD-PUBLIC GSHC'!I18="","",'COMMANDE GD-PUBLIC GSHC'!I18) -> 0.75
B45: =IF('COMMANDE GD-PUBLIC GSHC'!D19="","",'COMMANDE GD-PUBLIC GSHC'!D19) | C45: =IF('COMMANDE GD-PUBLIC GSHC'!C19="","",'COMMANDE GD-PUBLIC GSHC'!C19) | D45: =IF('COMMANDE GD-PUBLIC GSHC'!I19="","",'COMMANDE GD-PUBLIC GSHC'!I19) -> 0.77083333
B46: =IF('COMMANDE GD-PUBLIC GSHC'!D20="","",'COMMANDE GD-PUBLIC GSHC'!D20) | C46: =IF('COMMANDE GD-PUBLIC GSHC'!C20="","",'COMMANDE GD-PUBLIC GSHC'!C20) | D46: =IF('COMMANDE GD-PUBLIC GSHC'!I20="","",'COMMANDE GD-PUBLIC GSHC'!I20) -> 0.79166667
B47: =IF('COMMANDE GD-PUBLIC GSHC'!D21="","",'COMMANDE GD-PUBLIC GSHC'!D21) | C47: =IF('COMMANDE GD-PUBLIC GSHC'!C21="","",'COMMANDE GD-PUBLIC GSHC'!C21) | D47: =IF('COMMANDE GD-PUBLIC GSHC'!I21="","",'COMMANDE GD-PUBLIC GSHC'!I21)
B48: =IF('COMMANDE GD-PUBLIC GSHC'!D22="","",'COMMANDE GD-PUBLIC GSHC'!D22) | C48: =IF('COMMANDE GD-PUBLIC GSHC'!C22="","",'COMMANDE GD-PUBLIC GSHC'!C22) | D48: =IF('COMMANDE GD-PUBLIC GSHC'!I22="","",'COMMANDE GD-PUBLIC GSHC'!I22)
B53: ='COMMANDE GD-PUBLIC GSHC'!$A$2 -> MATCH GSHC X | C53: ='COMMANDE GD-PUBLIC GSHC'!$C$2 -> SCL TIGERS | E53: DATE | F53: ='COMMANDE GD-PUBLIC GSHC'!$D$2 -> 45974
B55: HEURE DÉBUT MATCH | C55: ='COMMANDE GD-PUBLIC GSHC'!$J$2 -> 0.82291667 | E55: LIEU | F55: PATINOIRE DES VERNETS
B58: POINT DE VENTE | C58: FONCTION | D58: HORAIRES DE PRÉSENCE | H58: SIGNATURE
B59: ='COMMANDE GD-PUBLIC GSHC'!A23 -> FOOD 1 | D59: ARRIVÉE | E59: PAUSE | F59: DÉPART | G59: REMARQUE / APPRÉCIATION PAR LE RESPONSABLE
B60: =IF('COMMANDE GD-PUBLIC GSHC'!D23="","",'COMMANDE GD-PUBLIC GSHC'!D23) | C60: =IF('COMMANDE GD-PUBLIC GSHC'!C23="","",'COMMANDE GD-PUBLIC GSHC'!C23) | D60: =IF('COMMANDE GD-PUBLIC GSHC'!I23="","",'COMMANDE GD-PUBLIC GSHC'!I23) -> 0.75
B61: =IF('COMMANDE GD-PUBLIC GSHC'!D24="","",'COMMANDE GD-PUBLIC GSHC'!D24) | C61: =IF('COMMANDE GD-PUBLIC GSHC'!C24="","",'COMMANDE GD-PUBLIC GSHC'!C24) | D61: =IF('COMMANDE GD-PUBLIC GSHC'!I24="","",'COMMANDE GD-PUBLIC GSHC'!I24) -> 0.72916667
B62: =IF('COMMANDE GD-PUBLIC GSHC'!D25="","",'COMMANDE GD-PUBLIC GSHC'!D25) | C62: =IF('COMMANDE GD-PUBLIC GSHC'!C25="","",'COMMANDE GD-PUBLIC GSHC'!C25) | D62: =IF('COMMANDE GD-PUBLIC GSHC'!I25="","",'COMMANDE GD-PUBLIC GSHC'!I25)
B63: =IF('COMMANDE GD-PUBLIC GSHC'!D26="","",'COMMANDE GD-PUBLIC GSHC'!D26) | C63: =IF('COMMANDE GD-PUBLIC GSHC'!C26="","",'COMMANDE GD-PUBLIC GSHC'!C26) | D63: =IF('COMMANDE GD-PUBLIC GSHC'!I26="","",'COMMANDE GD-PUBLIC GSHC'!I26)
B68: ='COMMANDE GD-PUBLIC GSHC'!$A$2 -> MATCH GSHC X | C68: ='COMMANDE GD-PUBLIC GSHC'!$C$2 -> SCL TIGERS | E68: DATE | F68: ='COMMANDE GD-PUBLIC GSHC'!$D$2 -> 45974
B70: HEURE DÉBUT MATCH | C70: ='COMMANDE GD-PUBLIC GSHC'!$J$2 -> 0.82291667 | E70: LIEU | F70: PATINOIRE DES VERNETS
...

Sheet Feuilles Heures a remplir GSHC
B2: ='COMMANDE GD-PUBLIC GSHC'!$A$2 -> MATCH GSHC X | C2: ='COMMANDE GD-PUBLIC GSHC'!$C$2 -> SCL TIGERS | E2: DATE | F2: ='COMMANDE GD-PUBLIC GSHC'!$D$2 -> 45974
B4: HEURE DÉBUT MATCH | C4: ='COMMANDE GD-PUBLIC GSHC'!$J$2 -> 0.82291667 | E4: LIEU | F4: PATINOIRE DES VERNETS
B7: POINT DE VENTE | C7: FONCTION | D7: HORAIRES DE PRÉSENCE | H7: SIGNATURE
B8: ='COMMANDE GD-PUBLIC GSHC'!A5 -> BEV 1 | D8: ARRIVÉE | E8: PAUSE | F8: DÉPART | G8: REMARQUE / APPRÉCIATION PAR LE RESPONSABLE
B9: =IF('COMMANDE GD-PUBLIC GSHC'!D5="","",'COMMANDE GD-PUBLIC GSHC'!D5) | C9: =IF('COMMANDE GD-PUBLIC GSHC'!C5="","",'COMMANDE GD-PUBLIC GSHC'!C5) | D9: =IF('COMMANDE GD-PUBLIC GSHC'!I5="","",'COMMANDE GD-PUBLIC GSHC'!I5) -> 0.72916667 | H9: FALSE
B10: =IF('COMMANDE GD-PUBLIC GSHC'!D6="","",'COMMANDE GD-PUBLIC GSHC'!D6) | C10: =IF('COMMANDE GD-PUBLIC GSHC'!C6="","",'COMMANDE GD-PUBLIC GSHC'!C6) | D10: =IF('COMMANDE GD-PUBLIC GSHC'!I6="","",'COMMANDE GD-PUBLIC GSHC'!I6) -> 0.75 | H10: FALSE
B11: =IF('COMMANDE GD-PUBLIC GSHC'!D7="","",'COMMANDE GD-PUBLIC GSHC'!D7) | C11: =IF('COMMANDE GD-PUBLIC GSHC'!C7="","",'COMMANDE GD-PUBLIC GSHC'!C7) | D11: =IF('COMMANDE GD-PUBLIC GSHC'!I7="","",'COMMANDE GD-PUBLIC GSHC'!I7) -> 0.77083333 | H11: FALSE
B12: =IF('COMMANDE GD-PUBLIC GSHC'!D8="","",'COMMANDE GD-PUBLIC GSHC'!D8) | C12: =IF('COMMANDE GD-PUBLIC GSHC'!C8="","",'COMMANDE GD-PUBLIC GSHC'!C8) | D12: =IF('COMMANDE GD-PUBLIC GSHC'!I8="","",'COMMANDE GD-PUBLIC GSHC'!I8) -> 0.79166667 | H12: FALSE
B13: =IF('COMMANDE GD-PUBLIC GSHC'!D9="","",'COMMANDE GD-PUBLIC GSHC'!D9) | C13: =IF('COMMANDE GD-PUBLIC GSHC'!C9="","",'COMMANDE GD-PUBLIC GSHC'!C9) | D13: =IF('COMMANDE GD-PUBLIC GSHC'!I9="","",'COMMANDE GD-PUBLIC GSHC'!I9) | H13: FALSE
B14: =IF('COMMANDE GD-PUBLIC GSHC'!D10="","",'COMMANDE GD-PUBLIC GSHC'!D10) | C14: =IF('COMMANDE GD-PUBLIC GSHC'!C10="","",'COMMANDE GD-PUBLIC GSHC'!C10) | D14: =IF('COMMANDE GD-PUBLIC GSHC'!I10="","",'COMMANDE GD-PUBLIC GSHC'!I10) | H14: FALSE
H15: FALSE
B19: ='COMMANDE GD-PUBLIC GSHC'!$A$2 -> MATCH GSHC X | C19: ='COMMANDE GD-PUBLIC GSHC'!$C$2 -> SCL TIGERS | E19: DATE | F19: ='COMMANDE GD-PUBLIC GSHC'!$D$2 -> 45974
B21: HEURE DÉBUT MATCH | C21: ='COMMANDE GD-PUBLIC GSHC'!$J$2 -> 0.82291667 | E21: LIEU | F21: PATINOIRE DES VERNETS
B24: POINT DE VENTE | C24: FONCTION | D24: HORAIRES DE PRÉSENCE | H24: SIGNATURE
B25: ='COMMANDE GD-PUBLIC GSHC'!A11 -> BEV 2 | D25: ARRIVÉE | E25: PAUSE | F25: DÉPART | G25: REMARQUE / APPRÉCIATION PAR LE RESPONSABLE
B26: =IF('COMMANDE GD-PUBLIC GSHC'!D11="","",'COMMANDE GD-PUBLIC GSHC'!D11) | C26: =IF('COMMANDE GD-PUBLIC GSHC'!C11="","",'COMMANDE GD-PUBLIC GSHC'!C11) | D26: =IF('COMMANDE GD-PUBLIC GSHC'!I11="","",'COMMANDE GD-PUBLIC GSHC'!I11) -> 0.72916667 | H26: FALSE
B27: =IF('COMMANDE GD-PUBLIC GSHC'!D12="","",'COMMANDE GD-PUBLIC GSHC'!D12) | C27: =IF('COMMANDE GD-PUBLIC GSHC'!C12="","",'COMMANDE GD-PUBLIC GSHC'!C12) | D27: =IF('COMMANDE GD-PUBLIC GSHC'!I12="","",'COMMANDE GD-PUBLIC GSHC'!I12) -> 0.75 | H27: FALSE
B28: =IF('COMMANDE GD-PUBLIC GSHC'!D13="","",'COMMANDE GD-PUBLIC GSHC'!D13) | C28: =IF('COMMANDE GD-PUBLIC GSHC'!C13="","",'COMMANDE GD-PUBLIC GSHC'!C13) | D28: =IF('COMMANDE GD-PUBLIC GSHC'!I13="","",'COMMANDE GD-PUBLIC GSHC'!I13) -> 0.77083333 | H28: FALSE
B29: =IF('COMMANDE GD-PUBLIC GSHC'!D14="","",'COMMANDE GD-PUBLIC GSHC'!D14) | C29: =IF('COMMANDE GD-PUBLIC GSHC'!C14="","",'COMMANDE GD-PUBLIC GSHC'!C14) | D29: =IF('COMMANDE GD-PUBLIC GSHC'!I14="","",'COMMANDE GD-PUBLIC GSHC'!I14) -> 0.79166667 | H29: FALSE
B30: =IF('COMMANDE GD-PUBLIC GSHC'!D15="","",'COMMANDE GD-PUBLIC GSHC'!D15) | C30: =IF('COMMANDE GD-PUBLIC GSHC'!C15="","",'COMMANDE GD-PUBLIC GSHC'!C15) | D30: =IF('COMMANDE GD-PUBLIC GSHC'!I15="","",'COMMANDE GD-PUBLIC GSHC'!I15) | H30: FALSE
B31: =IF('COMMANDE GD-PUBLIC GSHC'!D16="","",'COMMANDE GD-PUBLIC GSHC'!D16) | C31: =IF('COMMANDE GD-PUBLIC GSHC'!C16="","",'COMMANDE GD-PUBLIC GSHC'!C16) | D31: =IF('COMMANDE GD-PUBLIC GSHC'!I16="","",'COMMANDE GD-PUBLIC GSHC'!I16) | H31: FALSE
H32: FALSE
B36: ='COMMANDE GD-PUBLIC GSHC'!$A$2 -> MATCH GSHC X | C36: ='COMMANDE GD-PUBLIC GSHC'!$C$2 -> SCL TIGERS | E36: DATE | F36: ='COMMANDE GD-PUBLIC GSHC'!$D$2 -> 45974
B38: HEURE DÉBUT MATCH | C38: ='COMMANDE GD-PUBLIC GSHC'!$J$2 -> 0.82291667 | E38: LIEU | F38: PATINOIRE DES VERNETS
B41: POINT DE VENTE | C41: FONCTION | D41: HORAIRES DE PRÉSENCE | H41: SIGNATURE
B42: ='COMMANDE GD-PUBLIC GSHC'!A17 -> BEV 3 | D42: ARRIVÉE | E42: PAUSE | F42: DÉPART | G42: REMARQUE / APPRÉCIATION PAR LE RESPONSABLE
B43: =IF('COMMANDE GD-PUBLIC GSHC'!D17="","",'COMMANDE GD-PUBLIC GSHC'!D17) | C43: =IF('COMMANDE GD-PUBLIC GSHC'!C17="","",'COMMANDE GD-PUBLIC GSHC'!C17) | D43: =IF('COMMANDE GD-PUBLIC GSHC'!I17="","",'COMMANDE GD-PUBLIC GSHC'!I17) -> 0.72916667 | H43: FALSE
B44: =IF('COMMANDE GD-PUBLIC GSHC'!D18="","",'COMMANDE GD-PUBLIC GSHC'!D18) | C44: =IF('COMMANDE GD-PUBLIC GSHC'!C18="","",'COMMANDE GD-PUBLIC GSHC'!C18) | D44: =IF('COMMANDE GD-PUBLIC GSHC'!I18="","",'COMMANDE GD-PUBLIC GSHC'!I18) -> 0.75 | H44: FALSE
B45: =IF('COMMANDE GD-PUBLIC GSHC'!D19="","",'COMMANDE GD-PUBLIC GSHC'!D19) | C45: =IF('COMMANDE GD-PUBLIC GSHC'!C19="","",'COMMANDE GD-PUBLIC GSHC'!C19) | D45: =IF('COMMANDE GD-PUBLIC GSHC'!I19="","",'COMMANDE GD-PUBLIC GSHC'!I19) -> 0.77083333 | H45: FALSE
B46: =IF('COMMANDE GD-PUBLIC GSHC'!D20="","",'COMMANDE GD-PUBLIC GSHC'!D20) | C46: =IF('COMMANDE GD-PUBLIC GSHC'!C20="","",'COMMANDE GD-PUBLIC GSHC'!C20) | D46: =IF('COMMANDE GD-PUBLIC GSHC'!I20="","",'COMMANDE GD-PUBLIC GSHC'!I20) -> 0.79166667 | H46: FALSE
B47: =IF('COMMANDE GD-PUBLIC GSHC'!D21="","",'COMMANDE GD-PUBLIC GSHC'!D21) | C47: =IF('COMMANDE GD-PUBLIC GSHC'!C21="","",'COMMANDE GD-PUBLIC GSHC'!C21) | D47: =IF('COMMANDE GD-PUBLIC GSHC'!I21="","",'COMMANDE GD-PUBLIC GSHC'!I21) | H47: FALSE
B48: =IF('COMMANDE GD-PUBLIC GSHC'!D22="","",'COMMANDE GD-PUBLIC GSHC'!D22) | C48: =IF('COMMANDE GD-PUBLIC GSHC'!C22="","",'COMMANDE GD-PUBLIC GSHC'!C22) | D48: =IF('COMMANDE GD-PUBLIC GSHC'!I22="","",'COMMANDE GD-PUBLIC GSHC'!I22) | H48: FALSE
H49: FALSE
B53: ='COMMANDE GD-PUBLIC GSHC'!$A$2 -> MATCH GSHC X | C53: ='COMMANDE GD-PUBLIC GSHC'!$C$2 -> SCL TIGERS | E53: DATE | F53: ='COMMANDE GD-PUBLIC GSHC'!$D$2 -> 45974
B55: HEURE DÉBUT MATCH | C55: ='COMMANDE GD-PUBLIC GSHC'!$J$2 -> 0.82291667 | E55: LIEU | F55: PATINOIRE DES VERNETS
B58: POINT DE VENTE | C58: FONCTION | D58: HORAIRES DE PRÉSENCE | H58: SIGNATURE
B59: ='COMMANDE GD-PUBLIC GSHC'!A23 -> FOOD 1 | D59: ARRIVÉE | E59: PAUSE | F59: DÉPART | G59: REMARQUE / APPRÉCIATION PAR LE RESPONSABLE
B60: =IF('COMMANDE GD-PUBLIC GSHC'!D23="","",'COMMANDE GD-PUBLIC GSHC'!D23) | C60: =IF('COMMANDE GD-PUBLIC GSHC'!C23="","",'COMMANDE GD-PUBLIC GSHC'!C23) | D60: =IF('COMMANDE GD-PUBLIC GSHC'!I23="","",'COMMANDE GD-PUBLIC GSHC'!I23) -> 0.75 | H60: FALSE
B61: =IF('COMMANDE GD-PUBLIC GSHC'!D24="","",'COMMANDE GD-PUBLIC GSHC'!D24) | C61: =IF('COMMANDE GD-PUBLIC GSHC'!C24="","",'COMMANDE GD-PUBLIC GSHC'!C24) | D61: 17h30 | H61: FALSE
B62: =IF('COMMANDE GD-PUBLIC GSHC'!D25="","",'COMMANDE GD-PUBLIC GSHC'!D25) | C62: =IF('COMMANDE GD-PUBLIC GSHC'!C25="","",'COMMANDE GD-PUBLIC GSHC'!C25) | D62: =IF('COMMANDE GD-PUBLIC GSHC'!I25="","",'COMMANDE GD-PUBLIC GSHC'!I25) | H62: FALSE
...

Sheet COMMANDE GD-PUBLIC SFC
I1: OUVERT | J1: MATCH
A2: MATCH SFC X | C2: FC THOUNE | D2: 45969 | I2: 0.79166667 | J2: 0.85416667 | S2: COLONNE MASQUÉE
A3: PARTIE PRIME | D3: PARTIE HOTELIS | I3: HORAIRES INFOS | U3: A | V3: B | W3: E | X3: F | Y3: G
A4: LIEU | B4: NBR | C4: POSTE | D4: NOM ET PRÉNOM | E4: N° CONTRAT | F4: EMAIL CANDIDATS | G4: N° TÉL | H4: SALAIRE HORAIRE | I4: DÉBUT | J4: FIN ESTIMÉE | K4: COLONNE MASQUÉE | L4: PAUSE | M4: TOTAL COLONNE MASQUÉE | N4: COLONNE MASQUÉE Nbr heure avant 6h après 23h | O4: TOTAL DÉCIMAL | P4: TOTAL HEURE NORMAL DÉCIMAL | Q4: TOTAL HEURE SUPPL. DÉCIMAL | S4: 0.25 | T4: 0.95833333 | U4: -0.95833333 | V4: -0.70833333 | W4: 0.00069444444 | X4: 0.040972222 | Y4: 8600
A5: NORD 1 | I5: 0.75 | J5: 0.9375 | K5: =J5+$Y$4 -> 8600.9375 | L5: 0 | M5: =IF($I5="","",IF($J5<$I5,($J5+86400)-$I5-$L5,$J5-$I5-$L5)) -> 0.1875 | N5: =IF(J5="","",IF(AND($U$4<=(J5-$T$4),(J5-$T$4)<=$V$4),(K5-$T$4),"00:00")+IF(AND($W$4<=(J5-$T$4),(J5-$T$4)<=$X$4),(J5-$T$4),"00:00")+IF(($S$4-I5)<0,"00:00",($S$4-I5))) -> 0 | O5: =IF($C5="","",(HOUR($M5)*60+MINUTE($M5))/60) | P5: =IF(O5="","",O5-Q5) | Q5: =IF($C5="","",(HOUR($N5)*60+MINUTE($N5))/60)
I6: 0.75 | J6: 0.89583333 | K6: =J6+$Y$4 -> 8600.8958 | L6: 0 | M6: =IF($I6="","",IF($J6<$I6,($J6+86400)-$I6-$L6,$J6-$I6-$L6)) -> 0.14583333 | N6: =IF(J6="","",IF(AND($U$4<=(J6-$T$4),(J6-$T$4)<=$V$4),(K6-$T$4),"00:00")+IF(AND($W$4<=(J6-$T$4),(J6-$T$4)<=$X$4),(J6-$T$4),"00:00")+IF(($S$4-I6)<0,"00:00",($S$4-I6))) -> 0 | O6: =IF($C6="","",(HOUR($M6)*60+MINUTE($M6))/60) | P6: =IF(O6="","",O6-Q6) | Q6: =IF($C6="","",(HOUR($N6)*60+MINUTE($N6))/60)
I7: 0.77083333 | J7: 0.89583333 | K7: =J7+$Y$4 -> 8600.8958 | L7: 0 | M7: =IF($I7="","",IF($J7<$I7,($J7+86400)-$I7-$L7,$J7-$I7-$L7)) -> 0.125 | N7: =IF(J7="","",IF(AND($U$4<=(J7-$T$4),(J7-$T$4)<=$V$4),(K7-$T$4),"00:00")+IF(AND($W$4<=(J7-$T$4),(J7-$T$4)<=$X$4),(J7-$T$4),"00:00")+IF(($S$4-I7)<0,"00:00",($S$4-I7))) -> 0 | O7: =IF($C7="","",(HOUR($M7)*60+MINUTE($M7))/60) | P7: =IF(O7="","",O7-Q7) | Q7: =IF($C7="","",(HOUR($N7)*60+MINUTE($N7))/60)
I8: 0.77083333 | J8: 0.9375 | K8: =J8+$Y$4 -> 8600.9375 | L8: 0 | M8: =IF($I8="","",IF($J8<$I8,($J8+86400)-$I8-$L8,$J8-$I8-$L8)) -> 0.16666667 | N8: =IF(J8="","",IF(AND($U$4<=(J8-$T$4),(J8-$T$4)<=$V$4),(K8-$T$4),"00:00")+IF(AND($W$4<=(J8-$T$4),(J8-$T$4)<=$X$4),(J8-$T$4),"00:00")+IF(($S$4-I8)<0,"00:00",($S$4-I8))) -> 0 | O8: =IF($C8="","",(HOUR($M8)*60+MINUTE($M8))/60) | P8: =IF(O8="","",O8-Q8) | Q8: =IF($C8="","",(HOUR($N8)*60+MINUTE($N8))/60)
I9: 0.79166667 | J9: 0.91666667 | K9: =J9+$Y$4 -> 8600.9167 | L9: 0 | M9: =IF($I9="","",IF($J9<$I9,($J9+86400)-$I9-$L9,$J9-$I9-$L9)) -> 0.125 | N9: =IF(J9="","",IF(AND($U$4<=(J9-$T$4),(J9-$T$4)<=$V$4),(K9-$T$4),"00:00")+IF(AND($W$4<=(J9-$T$4),(J9-$T$4)<=$X$4),(J9-$T$4),"00:00")+IF(($S$4-I9)<0,"00:00",($S$4-I9))) -> 0 | O9: =IF($C9="","",(HOUR($M9)*60+MINUTE($M9))/60) | P9: =IF(O9="","",O9-Q9) | Q9: =IF($C9="","",(HOUR($N9)*60+MINUTE($N9))/60)
I10: 0.79166667 | J10: 0.91666667 | K10: =J10+$Y$4 -> 8600.9167 | L10: 0 | M10: =IF($I10="","",IF($J10<$I10,($J10+86400)-$I10-$L10,$J10-$I10-$L10)) -> 0.125 | N10: =IF(J10="","",IF(AND($U$4<=(J10-$T$4),(J10-$T$4)<=$V$4),(K10-$T$4),"00:00")+IF(AND($W$4<=(J10-$T$4),(J10-$T$4)<=$X$4),(J10-$T$4),"00:00")+IF(($S$4-I10)<0,"00:00",($S$4-I10))) -> 0 | O10: =IF($C10="","",(HOUR($M10)*60+MINUTE($M10))/60) | P10: =IF(O10="","",O10-Q10) | Q10: =IF($C10="","",(HOUR($N10)*60+MINUTE($N10))/60)
I11: 0.79166667 | J11: 0.91666667 | K11: =J11+$Y$4 -> 8600.9167 | L11: 0 | M11: =IF($I11="","",IF($J11<$I11,($J11+86400)-$I11-$L11,$J11-$I11-$L11)) -> 0.125 | N11: =IF(J11="","",IF(AND($U$4<=(J11-$T$4),(J11-$T$4)<=$V$4),(K11-$T$4),"00:00")+IF(AND($W$4<=(J11-$T$4),(J11-$T$4)<=$X$4),(J11-$T$4),"00:00")+IF(($S$4-I11)<0,"00:00",($S$4-I11))) -> 0 | O11: =IF($C11="","",(HOUR($M11)*60+MINUTE($M11))/60) | P11: =IF(O11="","",O11-Q11) | Q11: =IF($C11="","",(HOUR($N11)*60+MINUTE($N11))/60)
I12: 0.8125 | J12: 0.9375 | K12: =J12+$Y$4 -> 8600.9375 | L12: 0 | M12: =IF($I12="","",IF($J12<$I12,($J12+86400)-$I12-$L12,$J12-$I12-$L12)) -> 0.125 | N12: =IF(J12="","",IF(AND($U$4<=(J12-$T$4),(J12-$T$4)<=$V$4),(K12-$T$4),"00:00")+IF(AND($W$4<=(J12-$T$4),(J12-$T$4)<=$X$4),(J12-$T$4),"00:00")+IF(($S$4-I12)<0,"00:00",($S$4-I12))) -> 0 | O12: =IF($C12="","",(HOUR($M12)*60+MINUTE($M12))/60) | P12: =IF(O12="","",O12-Q12) | Q12: =IF($C12="","",(HOUR($N12)*60+MINUTE($N12))/60)
I13: 0.8125 | J13: 0.9375 | K13: =J13+$Y$4 -> 8600.9375 | L13: 0 | M13: =IF($I13="","",IF($J13<$I13,($J13+86400)-$I13-$L13,$J13-$I13-$L13)) -> 0.125 | N13: =IF(J13="","",IF(AND($U$4<=(J13-$T$4),(J13-$T$4)<=$V$4),(K13-$T$4),"00:00")+IF(AND($W$4<=(J13-$T$4),(J13-$T$4)<=$X$4),(J13-$T$4),"00:00")+IF(($S$4-I13)<0,"00:00",($S$4-I13))) -> 0 | O13: =IF($C13="","",(HOUR($M13)*60+MINUTE($M13))/60) | P13: =IF(O13="","",O13-Q13) | Q13: =IF($C13="","",(HOUR($N13)*60+MINUTE($N13))/60)
I14: 0.75 | J14: 0.91666667 | K14: =J14+$Y$4 -> 8600.9167 | L14: 0 | M14: =IF($I14="","",IF($J14<$I14,($J14+86400)-$I14-$L14,$J14-$I14-$L14)) -> 0.16666667 | N14: =IF(J14="","",IF(AND($U$4<=(J14-$T$4),(J14-$T$4)<=$V$4),(K14-$T$4),"00:00")+IF(AND($W$4<=(J14-$T$4),(J14-$T$4)<=$X$4),(J14-$T$4),"00:00")+IF(($S$4-I14)<0,"00:00",($S$4-I14))) -> 0 | O14: =IF($C14="","",(HOUR($M14)*60+MINUTE($M14))/60) | P14: =IF(O14="","",O14-Q14) | Q14: =IF($C14="","",(HOUR($N14)*60+MINUTE($N14))/60)
I15: 0.75 | J15: 0.91666667 | K15: =J15+$Y$4 -> 8600.9167 | L15: 0 | M15: =IF($I15="","",IF($J15<$I15,($J15+86400)-$I15-$L15,$J15-$I15-$L15)) -> 0.16666667 | N15: =IF(J15="","",IF(AND($U$4<=(J15-$T$4),(J15-$T$4)<=$V$4),(K15-$T$4),"00:00")+IF(AND($W$4<=(J15-$T$4),(J15-$T$4)<=$X$4),(J15-$T$4),"00:00")+IF(($S$4-I15)<0,"00:00",($S$4-I15))) -> 0 | O15: =IF($C15="","",(HOUR($M15)*60+MINUTE($M15))/60) | P15: =IF(O15="","",O15-Q15) | Q15: =IF($C15="","",(HOUR($N15)*60+MINUTE($N15))/60)
I16: 0.75 | J16: 0.91666667 | K16: =J16+$Y$4 -> 8600.9167 | L16: 0 | M16: =IF($I16="","",IF($J16<$I16,($J16+86400)-$I16-$L16,$J16-$I16-$L16)) -> 0.16666667 | N16: =IF(J16="","",IF(AND($U$4<=(J16-$T$4),(J16-$T$4)<=$V$4),(K16-$T$4),"00:00")+IF(AND($W$4<=(J16-$T$4),(J16-$T$4)<=$X$4),(J16-$T$4),"00:00")+IF(($S$4-I16)<0,"00:00",($S$4-I16))) -> 0 | O16: =IF($C16="","",(HOUR($M16)*60+MINUTE($M16))/60) | P16: =IF(O16="","",O16-Q16) | Q16: =IF($C16="","",(HOUR($N16)*60+MINUTE($N16))/60)
K17: =J17+$Y$4 -> 8600 | L17: 0 | M17: =IF($I17="","",IF($J17<$I17,($J17+86400)-$I17-$L17,$J17-$I17-$L17)) | N17: =IF(J17="","",IF(AND($U$4<=(J17-$T$4),(J17-$T$4)<=$V$4),(K17-$T$4),"00:00")+IF(AND($W$4<=(J17-$T$4),(J17-$T$4)<=$X$4),(J17-$T$4),"00:00")+IF(($S$4-I17)<0,"00:00",($S$4-I17))) | O17: =IF($C17="","",(HOUR($M17)*60+MINUTE($M17))/60) | P17: =IF(O17="","",O17-Q17) | Q17: =IF($C17="","",(HOUR($N17)*60+MINUTE($N17))/60)
A18: NORD 2 | I18: 0.75 | J18: 0.9375 | K18: =J18+$Y$4 -> 8600.9375 | L18: 0 | M18: =IF($I18="","",IF($J18<$I18,($J18+86400)-$I18-$L18,$J18-$I18-$L18)) -> 0.1875 | N18: =IF(J18="","",IF(AND($U$4<=(J18-$T$4),(J18-$T$4)<=$V$4),(K18-$T$4),"00:00")+IF(AND($W$4<=(J18-$T$4),(J18-$T$4)<=$X$4),(J18-$T$4),"00:00")+IF(($S$4-I18)<0,"00:00",($S$4-I18))) -> 0 | O18: =IF($C18="","",(HOUR($M18)*60+MINUTE($M18))/60) | P18: =IF(O18="","",O18-Q18) | Q18: =IF($C18="","",(HOUR($N18)*60+MINUTE($N18))/60)
I19: 0.75 | J19: 0.89583333 | K19: =J19+$Y$4 -> 8600.8958 | L19: 0 | M19: =IF($I19="","",IF($J19<$I19,($J19+86400)-$I19-$L19,$J19-$I19-$L19)) -> 0.14583333 | N19: =IF(J19="","",IF(AND($U$4<=(J19-$T$4),(J19-$T$4)<=$V$4),(K19-$T$4),"00:00")+IF(AND($W$4<=(J19-$T$4),(J19-$T$4)<=$X$4),(J19-$T$4),"00:00")+IF(($S$4-I19)<0,"00:00",($S$4-I19))) -> 0 | O19: =IF($C19="","",(HOUR($M19)*60+MINUTE($M19))/60) | P19: =IF(O19="","",O19-Q19) | Q19: =IF($C19="","",(HOUR($N19)*60+MINUTE($N19))/60)
I20: 0.77083333 | J20: 0.89583333 | K20: =J20+$Y$4 -> 8600.8958 | L20: 0 | M20: =IF($I20="","",IF($J20<$I20,($J20+86400)-$I20-$L20,$J20-$I20-$L20)) -> 0.125 | N20: =IF(J20="","",IF(AND($U$4<=(J20-$T$4),(J20-$T$4)<=$V$4),(K20-$T$4),"00:00")+IF(AND($W$4<=(J20-$T$4),(J20-$T$4)<=$X$4),(J20-$T$4),"00:00")+IF(($S$4-I20)<0,"00:00",($S$4-I20))) -> 0 | O20: =IF($C20="","",(HOUR($M20)*60+MINUTE($M20))/60) | P20: =IF(O20="","",O20-Q20) | Q20: =IF($C20="","",(HOUR($N20)*60+MINUTE($N20))/60)
I21: 0.77083333 | J21: 0.9375 | K21: =J21+$Y$4 -> 8600.9375 | L21: 0 | M21: =IF($I21="","",IF($J21<$I21,($J21+86400)-$I21-$L21,$J21-$I21-$L21)) -> 0.16666667 | N21: =IF(J21="","",IF(AND($U$4<=(J21-$T$4),(J21-$T$4)<=$V$4),(K21-$T$4),"00:00")+IF(AND($W$4<=(J21-$T$4),(J21-$T$4)<=$X$4),(J21-$T$4),"00:00")+IF(($S$4-I21)<0,"00:00",($S$4-I21))) -> 0 | O21: =IF($C21="","",(HOUR($M21)*60+MINUTE($M21))/60) | P21: =IF(O21="","",O21-Q21) | Q21: =IF($C21="","",(HOUR($N21)*60+MINUTE($N21))/60)
I22: 0.79166667 | J22: 0.91666667 | K22: =J22+$Y$4 -> 8600.9167 | L22: 0 | M22: =IF($I22="","",IF($J22<$I22,($J22+86400)-$I22-$L22,$J22-$I22-$L22)) -> 0.125 | N22: =IF(J22="","",IF(AND($U$4<=(J22-$T$4),(J22-$T$4)<=$V$4),(K22-$T$4),"00:00")+IF(AND($W$4<=(J22-$T$4),(J22-$T$4)<=$X$4),(J22-$T$4),"00:00")+IF(($S$4-I22)<0,"00:00",($S$4-I22))) -> 0 | O22: =IF($C22="","",(HOUR($M22)*60+MINUTE($M22))/60) | P22: =IF(O22="","",O22-Q22) | Q22: =IF($C22="","",(HOUR($N22)*60+MINUTE($N22))/60)
I23: 0.79166667 | J23: 0.91666667 | K23: =J23+$Y$4 -> 8600.9167 | L23: 0 | M23: =IF($I23="","",IF($J23<$I23,($J23+86400)-$I23-$L23,$J23-$I23-$L23)) -> 0.125 | N23: =IF(J23="","",IF(AND($U$4<=(J23-$T$4),(J23-$T$4)<=$V$4),(K23-$T$4),"00:00")+IF(AND($W$4<=(J23-$T$4),(J23-$T$4)<=$X$4),(J23-$T$4),"00:00")+IF(($S$4-I23)<0,"00:00",($S$4-I23))) -> 0 | O23: =IF($C23="","",(HOUR($M23)*60+MINUTE($M23))/60) | P23: =IF(O23="","",O23-Q23) | Q23: =IF($C23="","",(HOUR($N23)*60+MINUTE($N23))/60)
I24: 0.79166667 | J24: 0.91666667 | K24: =J24+$Y$4 -> 8600.9167 | L24: 0 | M24: =IF($I24="","",IF($J24<$I24,($J24+86400)-$I24-$L24,$J24-$I24-$L24)) -> 0.125 | N24: =IF(J24="","",IF(AND($U$4<=(J24-$T$4),(J24-$T$4)<=$V$4),(K24-$T$4),"00:00")+IF(AND($W$4<=(J24-$T$4),(J24-$T$4)<=$X$4),(J24-$T$4),"00:00")+IF(($S$4-I24)<0,"00:00",($S$4-I24))) -> 0 | O24: =IF($C24="","",(HOUR($M24)*60+MINUTE($M24))/60) | P24: =IF(O24="","",O24-Q24) | Q24: =IF($C24="","",(HOUR($N24)*60+MINUTE($N24))/60)
I25: 0.8125 | J25: 0.9375 | K25: =J25+$Y$4 -> 8600.9375 | L25: 0 | M25: =IF($I25="","",IF($J25<$I25,($J25+86400)-$I25-$L25,$J25-$I25-$L25)) -> 0.125 | N25: =IF(J25="","",IF(AND($U$4<=(J25-$T$4),(J25-$T$4)<=$V$4),(K25-$T$4),"00:00")+IF(AND($W$4<=(J25-$T$4),(J25-$T$4)<=$X$4),(J25-$T$4),"00:00")+IF(($S$4-I25)<0,"00:00",($S$4-I25))) -> 0 | O25: =IF($C25="","",(HOUR($M25)*60+MINUTE($M25))/60) | P25: =IF(O25="","",O25-Q25) | Q25: =IF($C25="","",(HOUR($N25)*60+MINUTE($N25))/60)
I26: 0.8125 | J26: 0.9375 | K26: =J26+$Y$4 -> 8600.9375 | L26: 0 | M26: =IF($I26="","",IF($J26<$I26,($J26+86400)-$I26-$L26,$J26-$I26-$L26)) -> 0.125 | N26: =IF(J26="","",IF(AND($U$4<=(J26-$T$4),(J26-$T$4)<=$V$4),(K26-$T$4),"00:00")+IF(AND($W$4<=(J26-$T$4),(J26-$T$4)<=$X$4),(J26-$T$4),"00:00")+IF(($S$4-I26)<0,"00:00",($S$4-I26))) -> 0 | O26: =IF($C26="","",(HOUR($M26)*60+MINUTE($M26))/60) | P26: =IF(O26="","",O26-Q26) | Q26: =IF($C26="","",(HOUR($N26)*60+MINUTE($N26))/60)
I27: 0.75 | J27: 0.91666667 | K27: =J27+$Y$4 -> 8600.9167 | L27: 0 | M27: =IF($I27="","",IF($J27<$I27,($J27+86400)-$I27-$L27,$J27-$I27-$L27)) -> 0.16666667 | N27: =IF(J27="","",IF(AND($U$4<=(J27-$T$4),(J27-$T$4)<=$V$4),(K27-$T$4),"00:00")+IF(AND($W$4<=(J27-$T$4),(J27-$T$4)<=$X$4),(J27-$T$4),"00:00")+IF(($S$4-I27)<0,"00:00",($S$4-I27))) -> 0 | O27: =IF($C27="","",(HOUR($M27)*60+MINUTE($M27))/60) | P27: =IF(O27="","",O27-Q27) | Q27: =IF($C27="","",(HOUR($N27)*60+MINUTE($N27))/60)
I28: 0.75 | J28: 0.91666667 | K28: =J28+$Y$4 -> 8600.9167 | L28: 0 | M28: =IF($I28="","",IF($J28<$I28,($J28+86400)-$I28-$L28,$J28-$I28-$L28)) -> 0.16666667 | N28: =IF(J28="","",IF(AND($U$4<=(J28-$T$4),(J28-$T$4)<=$V$4),(K28-$T$4),"00:00")+IF(AND($W$4<=(J28-$T$4),(J28-$T$4)<=$X$4),(J28-$T$4),"00:00")+IF(($S$4-I28)<0,"00:00",($S$4-I28))) -> 0 | O28: =IF($C28="","",(HOUR($M28)*60+MINUTE($M28))/60) | P28: =IF(O28="","",O28-Q28) | Q28: =IF($C28="","",(HOUR($N28)*60+MINUTE($N28))/60)
I29: 0.75 | J29: 0.91666667 | K29: =J29+$Y$4 -> 8600.9167 | L29: 0 | M29: =IF($I29="","",IF($J29<$I29,($J29+86400)-$I29-$L29,$J29-$I29-$L29)) -> 0.16666667 | N29: =IF(J29="","",IF(AND($U$4<=(J29-$T$4),(J29-$T$4)<=$V$4),(K29-$T$4),"00:00")+IF(AND($W$4<=(J29-$T$4),(J29-$T$4)<=$X$4),(J29-$T$4),"00:00")+IF(($S$4-I29)<0,"00:00",($S$4-I29))) -> 0 | O29: =IF($C29="","",(HOUR($M29)*60+MINUTE($M29))/60) | P29: =IF(O29="","",O29-Q29) | Q29: =IF($C29="","",(HOUR($N29)*60+MINUTE($N29))/60)
K30: =J30+$Y$4 -> 8600 | L30: 0 | M30: =IF($I30="","",IF($J30<$I30,($J30+86400)-$I30-$L30,$J30-$I30-$L30)) | N30: =IF(J30="","",IF(AND($U$4<=(J30-$T$4),(J30-$T$4)<=$V$4),(K30-$T$4),"00:00")+IF(AND($W$4<=(J30-$T$4),(J30-$T$4)<=$X$4),(J30-$T$4),"00:00")+IF(($S$4-I30)<0,"00:00",($S$4-I30))) | O30: =IF($C30="","",(HOUR($M30)*60+MINUTE($M30))/60) | P30: =IF(O30="","",O30-Q30) | Q30: =IF($C30="","",(HOUR($N30)*60+MINUTE($N30))/60)
A31: NORD MOBILE 1 | I31: 0.75 | J31: 0.9375 | K31: =J31+$Y$4 -> 8600.9375 | L31: 0 | M31: =IF($I31="","",IF($J31<$I31,($J31+86400)-$I31-$L31,$J31-$I31-$L31)) -> 0.1875 | N31: =IF(J31="","",IF(AND($U$4<=(J31-$T$4),(J31-$T$4)<=$V$4),(K31-$T$4),"00:00")+IF(AND($W$4<=(J31-$T$4),(J31-$T$4)<=$X$4),(J31-$T$4),"00:00")+IF(($S$4-I31)<0,"00:00",($S$4-I31))) -> 0 | O31: =IF($C31="","",(HOUR($M31)*60+MINUTE($M31))/60) | P31: =IF(O31="","",O31-Q31) | Q31: =IF($C31="","",(HOUR($N31)*60+MINUTE($N31))/60)
I32: 0.75 | J32: 0.89583333 | K32: =J32+$Y$4 -> 8600.8958 | L32: 0 | M32: =IF($I32="","",IF($J32<$I32,($J32+86400)-$I32-$L32,$J32-$I32-$L32)) -> 0.14583333 | N32: =IF(J32="","",IF(AND($U$4<=(J32-$T$4),(J32-$T$4)<=$V$4),(K32-$T$4),"00:00")+IF(AND($W$4<=(J32-$T$4),(J32-$T$4)<=$X$4),(J32-$T$4),"00:00")+IF(($S$4-I32)<0,"00:00",($S$4-I32))) -> 0 | O32: =IF($C32="","",(HOUR($M32)*60+MINUTE($M32))/60) | P32: =IF(O32="","",O32-Q32) | Q32: =IF($C32="","",(HOUR($N32)*60+MINUTE($N32))/60)
I33: 0.77083333 | J33: 0.89583333 | K33: =J33+$Y$4 -> 8600.8958 | L33: 0 | M33: =IF($I33="","",IF($J33<$I33,($J33+86400)-$I33-$L33,$J33-$I33-$L33)) -> 0.125 | N33: =IF(J33="","",IF(AND($U$4<=(J33-$T$4),(J33-$T$4)<=$V$4),(K33-$T$4),"00:00")+IF(AND($W$4<=(J33-$T$4),(J33-$T$4)<=$X$4),(J33-$T$4),"00:00")+IF(($S$4-I33)<0,"00:00",($S$4-I33))) -> 0 | O33: =IF($C33="","",(HOUR($M33)*60+MINUTE($M33))/60) | P33: =IF(O33="","",O33-Q33) | Q33: =IF($C33="","",(HOUR($N33)*60+MINUTE($N33))/60)
I34: 0.77083333 | J34: 0.89583333 | K34: =J34+$Y$4 -> 8600.8958 | L34: 0 | M34: =IF($I34="","",IF($J34<$I34,($J34+86400)-$I34-$L34,$J34-$I34-$L34)) -> 0.125 | N34: =IF(J34="","",IF(AND($U$4<=(J34-$T$4),(J34-$T$4)<=$V$4),(K34-$T$4),"00:00")+IF(AND($W$4<=(J34-$T$4),(J34-$T$4)<=$X$4),(J34-$T$4),"00:00")+IF(($S$4-I34)<0,"00:00",($S$4-I34))) -> 0 | O34: =IF($C34="","",(HOUR($M34)*60+MINUTE($M34))/60) | P34: =IF(O34="","",O34-Q34) | Q34: =IF($C34="","",(HOUR($N34)*60+MINUTE($N34))/60)
I35: 0.8125 | J35: 0.9375 | K35: =J35+$Y$4 -> 8600.9375 | L35: 0 | M35: =IF($I35="","",IF($J35<$I35,($J35+86400)-$I35-$L35,$J35-$I35-$L35)) -> 0.125 | N35: =IF(J35="","",IF(AND($U$4<=(J35-$T$4),(J35-$T$4)<=$V$4),(K35-$T$4),"00:00")+IF(AND($W$4<=(J35-$T$4),(J35-$T$4)<=$X$4),(J35-$T$4),"00:00")+IF(($S$4-I35)<0,"00:00",($S$4-I35))) -> 0 | O35: =IF($C35="","",(HOUR($M35)*60+MINUTE($M35))/60) | P35: =IF(O35="","",O35-Q35) | Q35: =IF($C35="","",(HOUR($N35)*60+MINUTE($N35))/60)
I36: 0.8125 | J36: 0.9375 | K36: =J36+$Y$4 -> 8600.9375 | L36: 0 | M36: =IF($I36="","",IF($J36<$I36,($J36+86400)-$I36-$L36,$J36-$I36-$L36)) -> 0.125 | N36: =IF(J36="","",IF(AND($U$4<=(J36-$T$4),(J36-$T$4)<=$V$4),(K36-$T$4),"00:00")+IF(AND($W$4<=(J36-$T$4),(J36-$T$4)<=$X$4),(J36-$T$4),"00:00")+IF(($S$4-I36)<0,"00:00",($S$4-I36))) -> 0 | O36: =IF($C36="","",(HOUR($M36)*60+MINUTE($M36))/60) | P36: =IF(O36="","",O36-Q36) | Q36: =IF($C36="","",(HOUR($N36)*60+MINUTE($N36))/60)
I37: 0.8125 | J37: 0.9375 | K37: =J37+$Y$4 -> 8600.9375 | L37: 0 | M37: =IF($I37="","",IF($J37<$I37,($J37+86400)-$I37-$L37,$J37-$I37-$L37)) -> 0.125 | N37: =IF(J37="","",IF(AND($U$4<=(J37-$T$4),(J37-$T$4)<=$V$4),(K37-$T$4),"00:00")+IF(AND($W$4<=(J37-$T$4),(J37-$T$4)<=$X$4),(J37-$T$4),"00:00")+IF(($S$4-I37)<0,"00:00",($S$4-I37))) -> 0 | O37: =IF($C37="","",(HOUR($M37)*60+MINUTE($M37))/60) | P37: =IF(O37="","",O37-Q37) | Q37: =IF($C37="","",(HOUR($N37)*60+MINUTE($N37))/60)
K38: =J38+$Y$4 -> 8600 | L38: 0 | M38: =IF($I38="","",IF($J38<$I38,($J38+86400)-$I38-$L38,$J38-$I38-$L38)) | N38: =IF(J38="","",IF(AND($U$4<=(J38-$T$4),(J38-$T$4)<=$V$4),(K38-$T$4),"00:00")+IF(AND($W$4<=(J38-$T$4),(J38-$T$4)<=$X$4),(J38-$T$4),"00:00")+IF(($S$4-I38)<0,"00:00",($S$4-I38))) | O38: =IF($C38="","",(HOUR($M38)*60+MINUTE($M38))/60) | P38: =IF(O38="","",O38-Q38) | Q38: =IF($C38="","",(HOUR($N38)*60+MINUTE($N38))/60)
K39: =J39+$Y$4 -> 8600 | L39: 0 | M39: =IF($I39="","",IF($J39<$I39,($J39+86400)-$I39-$L39,$J39-$I39-$L39)) | N39: =IF(J39="","",IF(AND($U$4<=(J39-$T$4),(J39-$T$4)<=$V$4),(K39-$T$4),"00:00")+IF(AND($W$4<=(J39-$T$4),(J39-$T$4)<=$X$4),(J39-$T$4),"00:00")+IF(($S$4-I39)<0,"00:00",($S$4-I39))) | O39: =IF($C39="","",(HOUR($M39)*60+MINUTE($M39))/60) | P39: =IF(O39="","",O39-Q39) | Q39: =IF($C39="","",(HOUR($N39)*60+MINUTE($N39))/60)
A40: NORD MOBILE 2 | I40: 0.75 | J40: 0.9375 | K40: =J40+$Y$4 -> 8600.9375 | L40: 0 | M40: =IF($I40="","",IF($J40<$I40,($J40+86400)-$I40-$L40,$J40-$I40-$L40)) -> 0.1875 | N40: =IF(J40="","",IF(AND($U$4<=(J40-$T$4),(J40-$T$4)<=$V$4),(K40-$T$4),"00:00")+IF(AND($W$4<=(J40-$T$4),(J40-$T$4)<=$X$4),(J40-$T$4),"00:00")+IF(($S$4-I40)<0,"00:00",($S$4-I40))) -> 0 | O40: =IF($C40="","",(HOUR($M40)*60+MINUTE($M40))/60) | P40: =IF(O40="","",O40-Q40) | Q40: =IF($C40="","",(HOUR($N40)*60+MINUTE($N40))/60)
...

Sheet FEUILLES HEURES SFC
B2: ='COMMANDE GD-PUBLIC SFC'!$A$2 -> MATCH SFC X | C2: ='COMMANDE GD-PUBLIC SFC'!$C$2 -> FC THOUNE | E2: DATE | F2: ='COMMANDE GD-PUBLIC SFC'!$D$2 -> 45969
B4: HEURE DÉBUT MATCH | C4: ='COMMANDE GD-PUBLIC SFC'!$J$2 -> 0.85416667 | E4: LIEU | F4: STADE DE GENÈVE
B6: NOMBRE DE PERSONNE DEVANT SE TROUVER DANS LA BUVETTE | C6: =COUNTA('COMMANDE GD-PUBLIC SFC'!C5:C17) -> 0
B9: POINT DE VENTE | C9: FONCTION | D9: HORAIRES DE PRÉSENCE | H9: SIGNATURE
B10: ='COMMANDE GD-PUBLIC SFC'!A5 -> NORD 1 | D10: ARRIVÉE | E10: PAUSE | F10: DÉPART | G10: REMARQUE / APPRÉCIATION PAR LE RESPONSABLE
B11: =IF('COMMANDE GD-PUBLIC SFC'!D5="","",'COMMANDE GD-PUBLIC SFC'!D5) | C11: =IF('COMMANDE GD-PUBLIC SFC'!C5="","",'COMMANDE GD-PUBLIC SFC'!C5) | D11: =IF('COMMANDE GD-PUBLIC SFC'!I5="","",'COMMANDE GD-PUBLIC SFC'!I5) -> 0.75
B12: =IF('COMMANDE GD-PUBLIC SFC'!D6="","",'COMMANDE GD-PUBLIC SFC'!D6) | C12: =IF('COMMANDE GD-PUBLIC SFC'!C6="","",'COMMANDE GD-PUBLIC SFC'!C6) | D12: =IF('COMMANDE GD-PUBLIC SFC'!I6="","",'COMMANDE GD-PUBLIC SFC'!I6) -> 0.75
B13: =IF('COMMANDE GD-PUBLIC SFC'!D7="","",'COMMANDE GD-PUBLIC SFC'!D7) | C13: =IF('COMMANDE GD-PUBLIC SFC'!C7="","",'COMMANDE GD-PUBLIC SFC'!C7) | D13: =IF('COMMANDE GD-PUBLIC SFC'!I7="","",'COMMANDE GD-PUBLIC SFC'!I7) -> 0.77083333
B14: =IF('COMMANDE GD-PUBLIC SFC'!D8="","",'COMMANDE GD-PUBLIC SFC'!D8) | C14: =IF('COMMANDE GD-PUBLIC SFC'!C8="","",'COMMANDE GD-PUBLIC SFC'!C8) | D14: =IF('COMMANDE GD-PUBLIC SFC'!I8="","",'COMMANDE GD-PUBLIC SFC'!I8) -> 0.77083333
B15: =IF('COMMANDE GD-PUBLIC SFC'!D9="","",'COMMANDE GD-PUBLIC SFC'!D9) | C15: =IF('COMMANDE GD-PUBLIC SFC'!C9="","",'COMMANDE GD-PUBLIC SFC'!C9) | D15: =IF('COMMANDE GD-PUBLIC SFC'!I9="","",'COMMANDE GD-PUBLIC SFC'!I9) -> 0.79166667
B16: =IF('COMMANDE GD-PUBLIC SFC'!D10="","",'COMMANDE GD-PUBLIC SFC'!D10) | C16: =IF('COMMANDE GD-PUBLIC SFC'!C10="","",'COMMANDE GD-PUBLIC SFC'!C10) | D16: =IF('COMMANDE GD-PUBLIC SFC'!I10="","",'COMMANDE GD-PUBLIC SFC'!I10) -> 0.79166667
B17: =IF('COMMANDE GD-PUBLIC SFC'!D11="","",'COMMANDE GD-PUBLIC SFC'!D11) | C17: =IF('COMMANDE GD-PUBLIC SFC'!C11="","",'COMMANDE GD-PUBLIC SFC'!C11) | D17: =IF('COMMANDE GD-PUBLIC SFC'!I11="","",'COMMANDE GD-PUBLIC SFC'!I11) -> 0.79166667
B18: =IF('COMMANDE GD-PUBLIC SFC'!D12="","",'COMMANDE GD-PUBLIC SFC'!D12) | C18: =IF('COMMANDE GD-PUBLIC SFC'!C12="","",'COMMANDE GD-PUBLIC SFC'!C12) | D18: =IF('COMMANDE GD-PUBLIC SFC'!I12="","",'COMMANDE GD-PUBLIC SFC'!I12) -> 0.8125
B19: =IF('COMMANDE GD-PUBLIC SFC'!D13="","",'COMMANDE GD-PUBLIC SFC'!D13) | C19: =IF('COMMANDE GD-PUBLIC SFC'!C13="","",'COMMANDE GD-PUBLIC SFC'!C13) | D19: =IF('COMMANDE GD-PUBLIC SFC'!I13="","",'COMMANDE GD-PUBLIC SFC'!I13) -> 0.8125
B20: =IF('COMMANDE GD-PUBLIC SFC'!D14="","",'COMMANDE GD-PUBLIC SFC'!D14) | C20: =IF('COMMANDE GD-PUBLIC SFC'!C14="","",'COMMANDE GD-PUBLIC SFC'!C14) | D20: =IF('COMMANDE GD-PUBLIC SFC'!I14="","",'COMMANDE GD-PUBLIC SFC'!I14) -> 0.75
B21: =IF('COMMANDE GD-PUBLIC SFC'!D15="","",'COMMANDE GD-PUBLIC SFC'!D15) | C21: =IF('COMMANDE GD-PUBLIC SFC'!C15="","",'COMMANDE GD-PUBLIC SFC'!C15) | D21: =IF('COMMANDE GD-PUBLIC SFC'!I15="","",'COMMANDE GD-PUBLIC SFC'!I15) -> 0.75
B22: =IF('COMMANDE GD-PUBLIC SFC'!D16="","",'COMMANDE GD-PUBLIC SFC'!D16) | C22: =IF('COMMANDE GD-PUBLIC SFC'!C16="","",'COMMANDE GD-PUBLIC SFC'!C16) | D22: =IF('COMMANDE GD-PUBLIC SFC'!I16="","",'COMMANDE GD-PUBLIC SFC'!I16) -> 0.75
B23: =IF('COMMANDE GD-PUBLIC SFC'!D17="","",'COMMANDE GD-PUBLIC SFC'!D17) | C23: =IF('COMMANDE GD-PUBLIC SFC'!C17="","",'COMMANDE GD-PUBLIC SFC'!C17)
B28: ='COMMANDE GD-PUBLIC SFC'!$A$2 -> MATCH SFC X | C28: ='COMMANDE GD-PUBLIC SFC'!$C$2 -> FC THOUNE | E28: DATE | F28: ='COMMANDE GD-PUBLIC SFC'!$D$2 -> 45969
B30: HEURE DÉBUT MATCH | C30: ='COMMANDE GD-PUBLIC SFC'!$J$2 -> 0.85416667 | E30: LIEU | F30: STADE DE GENÈVE
B32: NOMBRE DE PERSONNE DEVANT SE TROUVER DANS LA BUVETTE | C32: =COUNTA('COMMANDE GD-PUBLIC SFC'!C18:C30) -> 0
B35: POINT DE VENTE | C35: FONCTION | D35: HORAIRES DE PRÉSENCE | H35: SIGNATURE
B36: ='COMMANDE GD-PUBLIC SFC'!A18 -> NORD 2 | D36: ARRIVÉE | E36: PAUSE | F36: DÉPART | G36: REMARQUE / APPRÉCIATION PAR LE RESPONSABLE
B37: =IF('COMMANDE GD-PUBLIC SFC'!D18="","",'COMMANDE GD-PUBLIC SFC'!D18) | C37: =IF('COMMANDE GD-PUBLIC SFC'!C18="","",'COMMANDE GD-PUBLIC SFC'!C18) | D37: =IF('COMMANDE GD-PUBLIC SFC'!I18="","",'COMMANDE GD-PUBLIC SFC'!I18) -> 0.75
B38: =IF('COMMANDE GD-PUBLIC SFC'!D19="","",'COMMANDE GD-PUBLIC SFC'!D19) | C38: =IF('COMMANDE GD-PUBLIC SFC'!C19="","",'COMMANDE GD-PUBLIC SFC'!C19) | D38: =IF('COMMANDE GD-PUBLIC SFC'!I19="","",'COMMANDE GD-PUBLIC SFC'!I19) -> 0.75
B39: =IF('COMMANDE GD-PUBLIC SFC'!D20="","",'COMMANDE GD-PUBLIC SFC'!D20) | C39: =IF('COMMANDE GD-PUBLIC SFC'!C20="","",'COMMANDE GD-PUBLIC SFC'!C20) | D39: =IF('COMMANDE GD-PUBLIC SFC'!I20="","",'COMMANDE GD-PUBLIC SFC'!I20) -> 0.77083333
B40: =IF('COMMANDE GD-PUBLIC SFC'!D21="","",'COMMANDE GD-PUBLIC SFC'!D21) | C40: =IF('COMMANDE GD-PUBLIC SFC'!C21="","",'COMMANDE GD-PUBLIC SFC'!C21) | D40: =IF('COMMANDE GD-PUBLIC SFC'!I21="","",'COMMANDE GD-PUBLIC SFC'!I21) -> 0.77083333
B41: =IF('COMMANDE GD-PUBLIC SFC'!D22="","",'COMMANDE GD-PUBLIC SFC'!D22) | C41: =IF('COMMANDE GD-PUBLIC SFC'!C22="","",'COMMANDE GD-PUBLIC SFC'!C22) | D41: =IF('COMMANDE GD-PUBLIC SFC'!I22="","",'COMMANDE GD-PUBLIC SFC'!I22) -> 0.79166667
B42: =IF('COMMANDE GD-PUBLIC SFC'!D23="","",'COMMANDE GD-PUBLIC SFC'!D23) | C42: =IF('COMMANDE GD-PUBLIC SFC'!C23="","",'COMMANDE GD-PUBLIC SFC'!C23) | D42: =IF('COMMANDE GD-PUBLIC SFC'!I23="","",'COMMANDE GD-PUBLIC SFC'!I23) -> 0.79166667
B43: =IF('COMMANDE GD-PUBLIC SFC'!D24="","",'COMMANDE GD-PUBLIC SFC'!D24) | C43: =IF('COMMANDE GD-PUBLIC SFC'!C24="","",'COMMANDE GD-PUBLIC SFC'!C24) | D43: =IF('COMMANDE GD-PUBLIC SFC'!I24="","",'COMMANDE GD-PUBLIC SFC'!I24) -> 0.79166667
B44: =IF('COMMANDE GD-PUBLIC SFC'!D25="","",'COMMANDE GD-PUBLIC SFC'!D25) | C44: =IF('COMMANDE GD-PUBLIC SFC'!C25="","",'COMMANDE GD-PUBLIC SFC'!C25) | D44: =IF('COMMANDE GD-PUBLIC SFC'!I25="","",'COMMANDE GD-PUBLIC SFC'!I25) -> 0.8125
B45: =IF('COMMANDE GD-PUBLIC SFC'!D26="","",'COMMANDE GD-PUBLIC SFC'!D26) | C45: =IF('COMMANDE GD-PUBLIC SFC'!C26="","",'COMMANDE GD-PUBLIC SFC'!C26) | D45: =IF('COMMANDE GD-PUBLIC SFC'!I26="","",'COMMANDE GD-PUBLIC SFC'!I26) -> 0.8125
B46: =IF('COMMANDE GD-PUBLIC SFC'!D27="","",'COMMANDE GD-PUBLIC SFC'!D27) | C46: =IF('COMMANDE GD-PUBLIC SFC'!C27="","",'COMMANDE GD-PUBLIC SFC'!C27) | D46: =IF('COMMANDE GD-PUBLIC SFC'!I27="","",'COMMANDE GD-PUBLIC SFC'!I27) -> 0.75
B47: =IF('COMMANDE GD-PUBLIC SFC'!D28="","",'COMMANDE GD-PUBLIC SFC'!D28) | C47: =IF('COMMANDE GD-PUBLIC SFC'!C28="","",'COMMANDE GD-PUBLIC SFC'!C28) | D47: =IF('COMMANDE GD-PUBLIC SFC'!I28="","",'COMMANDE GD-PUBLIC SFC'!I28) -> 0.75
B48: =IF('COMMANDE GD-PUBLIC SFC'!D29="","",'COMMANDE GD-PUBLIC SFC'!D29) | C48: =IF('COMMANDE GD-PUBLIC SFC'!C29="","",'COMMANDE GD-PUBLIC SFC'!C29) | D48: =IF('COMMANDE GD-PUBLIC SFC'!I29="","",'COMMANDE GD-PUBLIC SFC'!I29) -> 0.75
B49: =IF('COMMANDE GD-PUBLIC SFC'!D30="","",'COMMANDE GD-PUBLIC SFC'!D30) | C49: =IF('COMMANDE GD-PUBLIC SFC'!C30="","",'COMMANDE GD-PUBLIC SFC'!C30) | D49: =IF('COMMANDE GD-PUBLIC SFC'!I30="","",'COMMANDE GD-PUBLIC SFC'!I30)
B53: ='COMMANDE GD-PUBLIC SFC'!$A$2 -> MATCH SFC X | C53: ='COMMANDE GD-PUBLIC SFC'!$C$2 -> FC THOUNE | E53: DATE | F53: ='COMMANDE GD-PUBLIC SFC'!$D$2 -> 45969
B55: HEURE DÉBUT MATCH | C55: ='COMMANDE GD-PUBLIC SFC'!$J$2 -> 0.85416667 | E55: LIEU | F55: STADE DE GENÈVE
B57: NOMBRE DE PERSONNE DEVANT SE TROUVER DANS LA BUVETTE | C57: =COUNTA('COMMANDE GD-PUBLIC SFC'!C31:C39) -> 0
B60: POINT DE VENTE | C60: FONCTION | D60: HORAIRES DE PRÉSENCE | H60: SIGNATURE
...
